[2023-08-18 09:58:50,743] - [com.zaxxer.hikari.pool.HikariPool] [run] -> (WARN) [HikariPool-21 - Thread starvation or clock leap detected (housekeeper delta=15h59m25s272ms827Âµs200ns).] 
[2023-08-18 09:59:04,485] - [org.hibernate.engine.jdbc.spi.SqlExceptionHelper] [logExceptions] -> (WARN) [SQL Error: 0, SQLState: 08S01] 
[2023-08-18 09:59:04,486] - [org.hibernate.engine.jdbc.spi.SqlExceptionHelper] [logExceptions] -> (ERROR) [HikariPool-21 - Connection is not available, request timed out after 57565146ms.] 
[2023-08-18 09:59:04,486] - [org.hibernate.engine.jdbc.spi.SqlExceptionHelper] [logExceptions] -> (ERROR) [Communications link failure

The last packet sent successfully to the server was 0 milliseconds ago. The driver has not received any packets from the server.] 
[2023-08-18 09:59:04,488] - [org.camunda.bpm.engine.jobexecutor] [logError] -> (ERROR) [ENGINE-14019 Exception during job acquisition Could not open JPA EntityManager for transaction; nested exception is org.hibernate.exception.JDBCConnectionException: Unable to acquire JDBC Connection] 
org.springframework.transaction.CannotCreateTransactionException: Could not open JPA EntityManager for transaction; nested exception is org.hibernate.exception.JDBCConnectionException: Unable to acquire JDBC Connection
	at org.springframework.orm.jpa.JpaTransactionManager.doBegin(JpaTransactionManager.java:467) ~[spring-orm-5.3.22.jar:5.3.22]
	at org.springframework.transaction.support.AbstractPlatformTransactionManager.startTransaction(AbstractPlatformTransactionManager.java:400) ~[spring-tx-5.3.22.jar:5.3.22]
	at org.springframework.transaction.support.AbstractPlatformTransactionManager.getTransaction(AbstractPlatformTransactionManager.java:373) ~[spring-tx-5.3.22.jar:5.3.22]
	at org.springframework.transaction.support.TransactionTemplate.execute(TransactionTemplate.java:137) ~[spring-tx-5.3.22.jar:5.3.22]
	at org.camunda.bpm.engine.spring.SpringTransactionInterceptor.execute(SpringTransactionInterceptor.java:71) ~[camunda-engine-spring-7.18.0.jar:7.18.0]
	at org.camunda.bpm.engine.impl.interceptor.ProcessApplicationContextInterceptor.execute(ProcessApplicationContextInterceptor.java:70) ~[camunda-engine-7.18.0.jar:7.18.0]
	at org.camunda.bpm.engine.impl.interceptor.CommandCounterInterceptor.execute(CommandCounterInterceptor.java:35) ~[camunda-engine-7.18.0.jar:7.18.0]
	at org.camunda.bpm.engine.impl.interceptor.LogInterceptor.execute(LogInterceptor.java:33) ~[camunda-engine-7.18.0.jar:7.18.0]
	at org.camunda.bpm.engine.impl.interceptor.ExceptionCodeInterceptor.execute(ExceptionCodeInterceptor.java:55) ~[camunda-engine-7.18.0.jar:7.18.0]
	at org.camunda.bpm.engine.impl.jobexecutor.SequentialJobAcquisitionRunnable.acquireJobs(SequentialJobAcquisitionRunnable.java:164) ~[camunda-engine-7.18.0.jar:7.18.0]
	at org.camunda.bpm.engine.impl.jobexecutor.SequentialJobAcquisitionRunnable.run(SequentialJobAcquisitionRunnable.java:80) ~[camunda-engine-7.18.0.jar:7.18.0]
	at java.lang.Thread.run(Thread.java:834) ~[?:?]
Caused by: org.hibernate.exception.JDBCConnectionException: Unable to acquire JDBC Connection
	at org.hibernate.exception.internal.SQLExceptionTypeDelegate.convert(SQLExceptionTypeDelegate.java:48) ~[hibernate-core-5.6.11.Final.jar:5.6.11.Final]
	at org.hibernate.exception.internal.StandardSQLExceptionConverter.convert(StandardSQLExceptionConverter.java:37) ~[hibernate-core-5.6.11.Final.jar:5.6.11.Final]
	at org.hibernate.engine.jdbc.spi.SqlExceptionHelper.convert(SqlExceptionHelper.java:113) ~[hibernate-core-5.6.11.Final.jar:5.6.11.Final]
	at org.hibernate.engine.jdbc.spi.SqlExceptionHelper.convert(SqlExceptionHelper.java:99) ~[hibernate-core-5.6.11.Final.jar:5.6.11.Final]
	at org.hibernate.resource.jdbc.internal.LogicalConnectionManagedImpl.acquireConnectionIfNeeded(LogicalConnectionManagedImpl.java:111) ~[hibernate-core-5.6.11.Final.jar:5.6.11.Final]
	at org.hibernate.resource.jdbc.internal.LogicalConnectionManagedImpl.getPhysicalConnection(LogicalConnectionManagedImpl.java:138) ~[hibernate-core-5.6.11.Final.jar:5.6.11.Final]
	at org.hibernate.resource.jdbc.internal.LogicalConnectionManagedImpl.getConnectionForTransactionManagement(LogicalConnectionManagedImpl.java:276) ~[hibernate-core-5.6.11.Final.jar:5.6.11.Final]
	at org.hibernate.resource.jdbc.internal.LogicalConnectionManagedImpl.begin(LogicalConnectionManagedImpl.java:284) ~[hibernate-core-5.6.11.Final.jar:5.6.11.Final]
	at org.hibernate.resource.transaction.backend.jdbc.internal.JdbcResourceLocalTransactionCoordinatorImpl$TransactionDriverControlImpl.begin(JdbcResourceLocalTransactionCoordinatorImpl.java:246) ~[hibernate-core-5.6.11.Final.jar:5.6.11.Final]
	at org.hibernate.engine.transaction.internal.TransactionImpl.begin(TransactionImpl.java:83) ~[hibernate-core-5.6.11.Final.jar:5.6.11.Final]
	at org.springframework.orm.jpa.vendor.HibernateJpaDialect.beginTransaction(HibernateJpaDialect.java:164) ~[spring-orm-5.3.22.jar:5.3.22]
	at org.springframework.orm.jpa.JpaTransactionManager.doBegin(JpaTransactionManager.java:421) ~[spring-orm-5.3.22.jar:5.3.22]
	... 11 more
Caused by: java.sql.SQLTransientConnectionException: HikariPool-21 - Connection is not available, request timed out after 57565146ms.
	at com.zaxxer.hikari.pool.HikariPool.createTimeoutException(HikariPool.java:696) ~[HikariCP-4.0.3.jar:?]
	at com.zaxxer.hikari.pool.HikariPool.getConnection(HikariPool.java:197) ~[HikariCP-4.0.3.jar:?]
	at com.zaxxer.hikari.pool.HikariPool.getConnection(HikariPool.java:162) ~[HikariCP-4.0.3.jar:?]
	at com.zaxxer.hikari.HikariDataSource.getConnection(HikariDataSource.java:128) ~[HikariCP-4.0.3.jar:?]
	at org.hibernate.engine.jdbc.connections.internal.DatasourceConnectionProviderImpl.getConnection(DatasourceConnectionProviderImpl.java:122) ~[hibernate-core-5.6.11.Final.jar:5.6.11.Final]
	at org.hibernate.internal.NonContextualJdbcConnectionAccess.obtainConnection(NonContextualJdbcConnectionAccess.java:38) ~[hibernate-core-5.6.11.Final.jar:5.6.11.Final]
	at org.hibernate.resource.jdbc.internal.LogicalConnectionManagedImpl.acquireConnectionIfNeeded(LogicalConnectionManagedImpl.java:108) ~[hibernate-core-5.6.11.Final.jar:5.6.11.Final]
	at org.hibernate.resource.jdbc.internal.LogicalConnectionManagedImpl.getPhysicalConnection(LogicalConnectionManagedImpl.java:138) ~[hibernate-core-5.6.11.Final.jar:5.6.11.Final]
	at org.hibernate.resource.jdbc.internal.LogicalConnectionManagedImpl.getConnectionForTransactionManagement(LogicalConnectionManagedImpl.java:276) ~[hibernate-core-5.6.11.Final.jar:5.6.11.Final]
	at org.hibernate.resource.jdbc.internal.LogicalConnectionManagedImpl.begin(LogicalConnectionManagedImpl.java:284) ~[hibernate-core-5.6.11.Final.jar:5.6.11.Final]
	at org.hibernate.resource.transaction.backend.jdbc.internal.JdbcResourceLocalTransactionCoordinatorImpl$TransactionDriverControlImpl.begin(JdbcResourceLocalTransactionCoordinatorImpl.java:246) ~[hibernate-core-5.6.11.Final.jar:5.6.11.Final]
	at org.hibernate.engine.transaction.internal.TransactionImpl.begin(TransactionImpl.java:83) ~[hibernate-core-5.6.11.Final.jar:5.6.11.Final]
	at org.springframework.orm.jpa.vendor.HibernateJpaDialect.beginTransaction(HibernateJpaDialect.java:164) ~[spring-orm-5.3.22.jar:5.3.22]
	at org.springframework.orm.jpa.JpaTransactionManager.doBegin(JpaTransactionManager.java:421) ~[spring-orm-5.3.22.jar:5.3.22]
	... 11 more
Caused by: com.mysql.cj.jdbc.exceptions.CommunicationsException: Communications link failure

The last packet sent successfully to the server was 0 milliseconds ago. The driver has not received any packets from the server.
	at com.mysql.cj.jdbc.exceptions.SQLError.createCommunicationsException(SQLError.java:174) ~[mysql-connector-java-8.0.30.jar:8.0.30]
	at com.mysql.cj.jdbc.exceptions.SQLExceptionsMapping.translateException(SQLExceptionsMapping.java:64) ~[mysql-connector-java-8.0.30.jar:8.0.30]
	at com.mysql.cj.jdbc.ConnectionImpl.createNewIO(ConnectionImpl.java:828) ~[mysql-connector-java-8.0.30.jar:8.0.30]
	at com.mysql.cj.jdbc.ConnectionImpl.<init>(ConnectionImpl.java:448) ~[mysql-connector-java-8.0.30.jar:8.0.30]
	at com.mysql.cj.jdbc.ConnectionImpl.getInstance(ConnectionImpl.java:241) ~[mysql-connector-java-8.0.30.jar:8.0.30]
	at com.mysql.cj.jdbc.NonRegisteringDriver.connect(NonRegisteringDriver.java:198) ~[mysql-connector-java-8.0.30.jar:8.0.30]
	at com.zaxxer.hikari.util.DriverDataSource.getConnection(DriverDataSource.java:138) ~[HikariCP-4.0.3.jar:?]
	at com.zaxxer.hikari.pool.PoolBase.newConnection(PoolBase.java:364) ~[HikariCP-4.0.3.jar:?]
	at com.zaxxer.hikari.pool.PoolBase.newPoolEntry(PoolBase.java:206) ~[HikariCP-4.0.3.jar:?]
	at com.zaxxer.hikari.pool.HikariPool.createPoolEntry(HikariPool.java:476) ~[HikariCP-4.0.3.jar:?]
	at com.zaxxer.hikari.pool.HikariPool.access$100(HikariPool.java:71) ~[HikariCP-4.0.3.jar:?]
	at com.zaxxer.hikari.pool.HikariPool$PoolEntryCreator.call(HikariPool.java:726) ~[HikariCP-4.0.3.jar:?]
	at com.zaxxer.hikari.pool.HikariPool$PoolEntryCreator.call(HikariPool.java:712) ~[HikariCP-4.0.3.jar:?]
	at java.util.concurrent.FutureTask.run(FutureTask.java:264) ~[?:?]
	at java.util.concurrent.ThreadPoolExecutor.runWorker(ThreadPoolExecutor.java:1128) ~[?:?]
	at java.util.concurrent.ThreadPoolExecutor$Worker.run(ThreadPoolExecutor.java:628) ~[?:?]
	... 1 more
Caused by: com.mysql.cj.exceptions.CJCommunicationsException: Communications link failure

The last packet sent successfully to the server was 0 milliseconds ago. The driver has not received any packets from the server.
	at jdk.internal.reflect.GeneratedConstructorAccessor477.newInstance(Unknown Source) ~[?:?]
	at jdk.internal.reflect.DelegatingConstructorAccessorImpl.newInstance(DelegatingConstructorAccessorImpl.java:45) ~[?:?]
	at java.lang.reflect.Constructor.newInstance(Constructor.java:490) ~[?:?]
	at com.mysql.cj.exceptions.ExceptionFactory.createException(ExceptionFactory.java:61) ~[mysql-connector-java-8.0.30.jar:8.0.30]
	at com.mysql.cj.exceptions.ExceptionFactory.createException(ExceptionFactory.java:105) ~[mysql-connector-java-8.0.30.jar:8.0.30]
	at com.mysql.cj.exceptions.ExceptionFactory.createException(ExceptionFactory.java:151) ~[mysql-connector-java-8.0.30.jar:8.0.30]
	at com.mysql.cj.exceptions.ExceptionFactory.createCommunicationsException(ExceptionFactory.java:167) ~[mysql-connector-java-8.0.30.jar:8.0.30]
	at com.mysql.cj.protocol.a.NativeSocketConnection.connect(NativeSocketConnection.java:89) ~[mysql-connector-java-8.0.30.jar:8.0.30]
	at com.mysql.cj.NativeSession.connect(NativeSession.java:120) ~[mysql-connector-java-8.0.30.jar:8.0.30]
	at com.mysql.cj.jdbc.ConnectionImpl.connectOneTryOnly(ConnectionImpl.java:948) ~[mysql-connector-java-8.0.30.jar:8.0.30]
	at com.mysql.cj.jdbc.ConnectionImpl.createNewIO(ConnectionImpl.java:818) ~[mysql-connector-java-8.0.30.jar:8.0.30]
	at com.mysql.cj.jdbc.ConnectionImpl.<init>(ConnectionImpl.java:448) ~[mysql-connector-java-8.0.30.jar:8.0.30]
	at com.mysql.cj.jdbc.ConnectionImpl.getInstance(ConnectionImpl.java:241) ~[mysql-connector-java-8.0.30.jar:8.0.30]
	at com.mysql.cj.jdbc.NonRegisteringDriver.connect(NonRegisteringDriver.java:198) ~[mysql-connector-java-8.0.30.jar:8.0.30]
	at com.zaxxer.hikari.util.DriverDataSource.getConnection(DriverDataSource.java:138) ~[HikariCP-4.0.3.jar:?]
	at com.zaxxer.hikari.pool.PoolBase.newConnection(PoolBase.java:364) ~[HikariCP-4.0.3.jar:?]
	at com.zaxxer.hikari.pool.PoolBase.newPoolEntry(PoolBase.java:206) ~[HikariCP-4.0.3.jar:?]
	at com.zaxxer.hikari.pool.HikariPool.createPoolEntry(HikariPool.java:476) ~[HikariCP-4.0.3.jar:?]
	at com.zaxxer.hikari.pool.HikariPool.access$100(HikariPool.java:71) ~[HikariCP-4.0.3.jar:?]
	at com.zaxxer.hikari.pool.HikariPool$PoolEntryCreator.call(HikariPool.java:726) ~[HikariCP-4.0.3.jar:?]
	at com.zaxxer.hikari.pool.HikariPool$PoolEntryCreator.call(HikariPool.java:712) ~[HikariCP-4.0.3.jar:?]
	at java.util.concurrent.FutureTask.run(FutureTask.java:264) ~[?:?]
	at java.util.concurrent.ThreadPoolExecutor.runWorker(ThreadPoolExecutor.java:1128) ~[?:?]
	at java.util.concurrent.ThreadPoolExecutor$Worker.run(ThreadPoolExecutor.java:628) ~[?:?]
	... 1 more
Caused by: java.net.UnknownHostException: No such host is known (freshersuperchargers.czbdrgtkozjs.us-east-1.rds.amazonaws.com)
	at java.net.Inet6AddressImpl.lookupAllHostAddr(Native Method) ~[?:?]
	at java.net.InetAddress$PlatformNameService.lookupAllHostAddr(InetAddress.java:929) ~[?:?]
	at java.net.InetAddress.getAddressesFromNameService(InetAddress.java:1538) ~[?:?]
	at java.net.InetAddress$NameServiceAddresses.get(InetAddress.java:848) ~[?:?]
	at java.net.InetAddress.getAllByName0(InetAddress.java:1527) ~[?:?]
	at java.net.InetAddress.getAllByName(InetAddress.java:1380) ~[?:?]
	at java.net.InetAddress.getAllByName(InetAddress.java:1302) ~[?:?]
	at com.mysql.cj.protocol.StandardSocketFactory.connect(StandardSocketFactory.java:130) ~[mysql-connector-java-8.0.30.jar:8.0.30]
	at com.mysql.cj.protocol.a.NativeSocketConnection.connect(NativeSocketConnection.java:63) ~[mysql-connector-java-8.0.30.jar:8.0.30]
	at com.mysql.cj.NativeSession.connect(NativeSession.java:120) ~[mysql-connector-java-8.0.30.jar:8.0.30]
	at com.mysql.cj.jdbc.ConnectionImpl.connectOneTryOnly(ConnectionImpl.java:948) ~[mysql-connector-java-8.0.30.jar:8.0.30]
	at com.mysql.cj.jdbc.ConnectionImpl.createNewIO(ConnectionImpl.java:818) ~[mysql-connector-java-8.0.30.jar:8.0.30]
	at com.mysql.cj.jdbc.ConnectionImpl.<init>(ConnectionImpl.java:448) ~[mysql-connector-java-8.0.30.jar:8.0.30]
	at com.mysql.cj.jdbc.ConnectionImpl.getInstance(ConnectionImpl.java:241) ~[mysql-connector-java-8.0.30.jar:8.0.30]
	at com.mysql.cj.jdbc.NonRegisteringDriver.connect(NonRegisteringDriver.java:198) ~[mysql-connector-java-8.0.30.jar:8.0.30]
	at com.zaxxer.hikari.util.DriverDataSource.getConnection(DriverDataSource.java:138) ~[HikariCP-4.0.3.jar:?]
	at com.zaxxer.hikari.pool.PoolBase.newConnection(PoolBase.java:364) ~[HikariCP-4.0.3.jar:?]
	at com.zaxxer.hikari.pool.PoolBase.newPoolEntry(PoolBase.java:206) ~[HikariCP-4.0.3.jar:?]
	at com.zaxxer.hikari.pool.HikariPool.createPoolEntry(HikariPool.java:476) ~[HikariCP-4.0.3.jar:?]
	at com.zaxxer.hikari.pool.HikariPool.access$100(HikariPool.java:71) ~[HikariCP-4.0.3.jar:?]
	at com.zaxxer.hikari.pool.HikariPool$PoolEntryCreator.call(HikariPool.java:726) ~[HikariCP-4.0.3.jar:?]
	at com.zaxxer.hikari.pool.HikariPool$PoolEntryCreator.call(HikariPool.java:712) ~[HikariCP-4.0.3.jar:?]
	at java.util.concurrent.FutureTask.run(FutureTask.java:264) ~[?:?]
	at java.util.concurrent.ThreadPoolExecutor.runWorker(ThreadPoolExecutor.java:1128) ~[?:?]
	at java.util.concurrent.ThreadPoolExecutor$Worker.run(ThreadPoolExecutor.java:628) ~[?:?]
	... 1 more
[2023-08-18 10:44:47,191] - [com.zaxxer.hikari.pool.HikariPool] [run] -> (WARN) [HikariPool-21 - Thread starvation or clock leap detected (housekeeper delta=5m50s503ms440Âµs600ns).] 
[2023-08-18 10:59:30,107] - [com.zaxxer.hikari.pool.PoolBase] [isConnectionAlive] -> (WARN) [HikariPool-21 - Failed to validate connection com.mysql.cj.jdbc.ConnectionImpl@74081377 (No operations allowed after connection closed.). Possibly consider using a shorter maxLifetime value.] 
[2023-08-18 10:59:30,120] - [com.zaxxer.hikari.pool.PoolBase] [isConnectionAlive] -> (WARN) [HikariPool-21 - Failed to validate connection com.mysql.cj.jdbc.ConnectionImpl@599e7fe (No operations allowed after connection closed.). Possibly consider using a shorter maxLifetime value.] 
[2023-08-18 10:59:57,251] - [org.hibernate.engine.jdbc.spi.SqlExceptionHelper] [logExceptions] -> (WARN) [SQL Error: 0, SQLState: 08S01] 
[2023-08-18 10:59:57,251] - [org.hibernate.engine.jdbc.spi.SqlExceptionHelper] [logExceptions] -> (ERROR) [HikariPool-21 - Connection is not available, request timed out after 30005ms.] 
[2023-08-18 10:59:57,251] - [org.hibernate.engine.jdbc.spi.SqlExceptionHelper] [logExceptions] -> (ERROR) [Communications link failure

The last packet sent successfully to the server was 0 milliseconds ago. The driver has not received any packets from the server.] 
[2023-08-18 10:59:57,252] - [org.camunda.bpm.engine.jobexecutor] [logError] -> (ERROR) [ENGINE-14019 Exception during job acquisition Could not open JPA EntityManager for transaction; nested exception is org.hibernate.exception.JDBCConnectionException: Unable to acquire JDBC Connection] 
org.springframework.transaction.CannotCreateTransactionException: Could not open JPA EntityManager for transaction; nested exception is org.hibernate.exception.JDBCConnectionException: Unable to acquire JDBC Connection
	at org.springframework.orm.jpa.JpaTransactionManager.doBegin(JpaTransactionManager.java:467) ~[spring-orm-5.3.22.jar:5.3.22]
	at org.springframework.transaction.support.AbstractPlatformTransactionManager.startTransaction(AbstractPlatformTransactionManager.java:400) ~[spring-tx-5.3.22.jar:5.3.22]
	at org.springframework.transaction.support.AbstractPlatformTransactionManager.getTransaction(AbstractPlatformTransactionManager.java:373) ~[spring-tx-5.3.22.jar:5.3.22]
	at org.springframework.transaction.support.TransactionTemplate.execute(TransactionTemplate.java:137) ~[spring-tx-5.3.22.jar:5.3.22]
	at org.camunda.bpm.engine.spring.SpringTransactionInterceptor.execute(SpringTransactionInterceptor.java:71) ~[camunda-engine-spring-7.18.0.jar:7.18.0]
	at org.camunda.bpm.engine.impl.interceptor.ProcessApplicationContextInterceptor.execute(ProcessApplicationContextInterceptor.java:70) ~[camunda-engine-7.18.0.jar:7.18.0]
	at org.camunda.bpm.engine.impl.interceptor.CommandCounterInterceptor.execute(CommandCounterInterceptor.java:35) ~[camunda-engine-7.18.0.jar:7.18.0]
	at org.camunda.bpm.engine.impl.interceptor.LogInterceptor.execute(LogInterceptor.java:33) ~[camunda-engine-7.18.0.jar:7.18.0]
	at org.camunda.bpm.engine.impl.interceptor.ExceptionCodeInterceptor.execute(ExceptionCodeInterceptor.java:55) ~[camunda-engine-7.18.0.jar:7.18.0]
	at org.camunda.bpm.engine.impl.jobexecutor.SequentialJobAcquisitionRunnable.acquireJobs(SequentialJobAcquisitionRunnable.java:164) ~[camunda-engine-7.18.0.jar:7.18.0]
	at org.camunda.bpm.engine.impl.jobexecutor.SequentialJobAcquisitionRunnable.run(SequentialJobAcquisitionRunnable.java:80) ~[camunda-engine-7.18.0.jar:7.18.0]
	at java.lang.Thread.run(Thread.java:834) ~[?:?]
Caused by: org.hibernate.exception.JDBCConnectionException: Unable to acquire JDBC Connection
	at org.hibernate.exception.internal.SQLExceptionTypeDelegate.convert(SQLExceptionTypeDelegate.java:48) ~[hibernate-core-5.6.11.Final.jar:5.6.11.Final]
	at org.hibernate.exception.internal.StandardSQLExceptionConverter.convert(StandardSQLExceptionConverter.java:37) ~[hibernate-core-5.6.11.Final.jar:5.6.11.Final]
	at org.hibernate.engine.jdbc.spi.SqlExceptionHelper.convert(SqlExceptionHelper.java:113) ~[hibernate-core-5.6.11.Final.jar:5.6.11.Final]
	at org.hibernate.engine.jdbc.spi.SqlExceptionHelper.convert(SqlExceptionHelper.java:99) ~[hibernate-core-5.6.11.Final.jar:5.6.11.Final]
	at org.hibernate.resource.jdbc.internal.LogicalConnectionManagedImpl.acquireConnectionIfNeeded(LogicalConnectionManagedImpl.java:111) ~[hibernate-core-5.6.11.Final.jar:5.6.11.Final]
	at org.hibernate.resource.jdbc.internal.LogicalConnectionManagedImpl.getPhysicalConnection(LogicalConnectionManagedImpl.java:138) ~[hibernate-core-5.6.11.Final.jar:5.6.11.Final]
	at org.hibernate.resource.jdbc.internal.LogicalConnectionManagedImpl.getConnectionForTransactionManagement(LogicalConnectionManagedImpl.java:276) ~[hibernate-core-5.6.11.Final.jar:5.6.11.Final]
	at org.hibernate.resource.jdbc.internal.LogicalConnectionManagedImpl.begin(LogicalConnectionManagedImpl.java:284) ~[hibernate-core-5.6.11.Final.jar:5.6.11.Final]
	at org.hibernate.resource.transaction.backend.jdbc.internal.JdbcResourceLocalTransactionCoordinatorImpl$TransactionDriverControlImpl.begin(JdbcResourceLocalTransactionCoordinatorImpl.java:246) ~[hibernate-core-5.6.11.Final.jar:5.6.11.Final]
	at org.hibernate.engine.transaction.internal.TransactionImpl.begin(TransactionImpl.java:83) ~[hibernate-core-5.6.11.Final.jar:5.6.11.Final]
	at org.springframework.orm.jpa.vendor.HibernateJpaDialect.beginTransaction(HibernateJpaDialect.java:164) ~[spring-orm-5.3.22.jar:5.3.22]
	at org.springframework.orm.jpa.JpaTransactionManager.doBegin(JpaTransactionManager.java:421) ~[spring-orm-5.3.22.jar:5.3.22]
	... 11 more
Caused by: java.sql.SQLTransientConnectionException: HikariPool-21 - Connection is not available, request timed out after 30005ms.
	at com.zaxxer.hikari.pool.HikariPool.createTimeoutException(HikariPool.java:696) ~[HikariCP-4.0.3.jar:?]
	at com.zaxxer.hikari.pool.HikariPool.getConnection(HikariPool.java:197) ~[HikariCP-4.0.3.jar:?]
	at com.zaxxer.hikari.pool.HikariPool.getConnection(HikariPool.java:162) ~[HikariCP-4.0.3.jar:?]
	at com.zaxxer.hikari.HikariDataSource.getConnection(HikariDataSource.java:128) ~[HikariCP-4.0.3.jar:?]
	at org.hibernate.engine.jdbc.connections.internal.DatasourceConnectionProviderImpl.getConnection(DatasourceConnectionProviderImpl.java:122) ~[hibernate-core-5.6.11.Final.jar:5.6.11.Final]
	at org.hibernate.internal.NonContextualJdbcConnectionAccess.obtainConnection(NonContextualJdbcConnectionAccess.java:38) ~[hibernate-core-5.6.11.Final.jar:5.6.11.Final]
	at org.hibernate.resource.jdbc.internal.LogicalConnectionManagedImpl.acquireConnectionIfNeeded(LogicalConnectionManagedImpl.java:108) ~[hibernate-core-5.6.11.Final.jar:5.6.11.Final]
	at org.hibernate.resource.jdbc.internal.LogicalConnectionManagedImpl.getPhysicalConnection(LogicalConnectionManagedImpl.java:138) ~[hibernate-core-5.6.11.Final.jar:5.6.11.Final]
	at org.hibernate.resource.jdbc.internal.LogicalConnectionManagedImpl.getConnectionForTransactionManagement(LogicalConnectionManagedImpl.java:276) ~[hibernate-core-5.6.11.Final.jar:5.6.11.Final]
	at org.hibernate.resource.jdbc.internal.LogicalConnectionManagedImpl.begin(LogicalConnectionManagedImpl.java:284) ~[hibernate-core-5.6.11.Final.jar:5.6.11.Final]
	at org.hibernate.resource.transaction.backend.jdbc.internal.JdbcResourceLocalTransactionCoordinatorImpl$TransactionDriverControlImpl.begin(JdbcResourceLocalTransactionCoordinatorImpl.java:246) ~[hibernate-core-5.6.11.Final.jar:5.6.11.Final]
	at org.hibernate.engine.transaction.internal.TransactionImpl.begin(TransactionImpl.java:83) ~[hibernate-core-5.6.11.Final.jar:5.6.11.Final]
	at org.springframework.orm.jpa.vendor.HibernateJpaDialect.beginTransaction(HibernateJpaDialect.java:164) ~[spring-orm-5.3.22.jar:5.3.22]
	at org.springframework.orm.jpa.JpaTransactionManager.doBegin(JpaTransactionManager.java:421) ~[spring-orm-5.3.22.jar:5.3.22]
	... 11 more
Caused by: com.mysql.cj.jdbc.exceptions.CommunicationsException: Communications link failure

The last packet sent successfully to the server was 0 milliseconds ago. The driver has not received any packets from the server.
	at com.mysql.cj.jdbc.exceptions.SQLError.createCommunicationsException(SQLError.java:174) ~[mysql-connector-java-8.0.30.jar:8.0.30]
	at com.mysql.cj.jdbc.exceptions.SQLExceptionsMapping.translateException(SQLExceptionsMapping.java:64) ~[mysql-connector-java-8.0.30.jar:8.0.30]
	at com.mysql.cj.jdbc.ConnectionImpl.createNewIO(ConnectionImpl.java:828) ~[mysql-connector-java-8.0.30.jar:8.0.30]
	at com.mysql.cj.jdbc.ConnectionImpl.<init>(ConnectionImpl.java:448) ~[mysql-connector-java-8.0.30.jar:8.0.30]
	at com.mysql.cj.jdbc.ConnectionImpl.getInstance(ConnectionImpl.java:241) ~[mysql-connector-java-8.0.30.jar:8.0.30]
	at com.mysql.cj.jdbc.NonRegisteringDriver.connect(NonRegisteringDriver.java:198) ~[mysql-connector-java-8.0.30.jar:8.0.30]
	at com.zaxxer.hikari.util.DriverDataSource.getConnection(DriverDataSource.java:138) ~[HikariCP-4.0.3.jar:?]
	at com.zaxxer.hikari.pool.PoolBase.newConnection(PoolBase.java:364) ~[HikariCP-4.0.3.jar:?]
	at com.zaxxer.hikari.pool.PoolBase.newPoolEntry(PoolBase.java:206) ~[HikariCP-4.0.3.jar:?]
	at com.zaxxer.hikari.pool.HikariPool.createPoolEntry(HikariPool.java:476) ~[HikariCP-4.0.3.jar:?]
	at com.zaxxer.hikari.pool.HikariPool.access$100(HikariPool.java:71) ~[HikariCP-4.0.3.jar:?]
	at com.zaxxer.hikari.pool.HikariPool$PoolEntryCreator.call(HikariPool.java:726) ~[HikariCP-4.0.3.jar:?]
	at com.zaxxer.hikari.pool.HikariPool$PoolEntryCreator.call(HikariPool.java:712) ~[HikariCP-4.0.3.jar:?]
	at java.util.concurrent.FutureTask.run(FutureTask.java:264) ~[?:?]
	at java.util.concurrent.ThreadPoolExecutor.runWorker(ThreadPoolExecutor.java:1128) ~[?:?]
	at java.util.concurrent.ThreadPoolExecutor$Worker.run(ThreadPoolExecutor.java:628) ~[?:?]
	... 1 more
Caused by: com.mysql.cj.exceptions.CJCommunicationsException: Communications link failure

The last packet sent successfully to the server was 0 milliseconds ago. The driver has not received any packets from the server.
	at jdk.internal.reflect.GeneratedConstructorAccessor491.newInstance(Unknown Source) ~[?:?]
	at jdk.internal.reflect.DelegatingConstructorAccessorImpl.newInstance(DelegatingConstructorAccessorImpl.java:45) ~[?:?]
	at java.lang.reflect.Constructor.newInstance(Constructor.java:490) ~[?:?]
	at com.mysql.cj.exceptions.ExceptionFactory.createException(ExceptionFactory.java:61) ~[mysql-connector-java-8.0.30.jar:8.0.30]
	at com.mysql.cj.exceptions.ExceptionFactory.createException(ExceptionFactory.java:105) ~[mysql-connector-java-8.0.30.jar:8.0.30]
	at com.mysql.cj.exceptions.ExceptionFactory.createException(ExceptionFactory.java:151) ~[mysql-connector-java-8.0.30.jar:8.0.30]
	at com.mysql.cj.exceptions.ExceptionFactory.createCommunicationsException(ExceptionFactory.java:167) ~[mysql-connector-java-8.0.30.jar:8.0.30]
	at com.mysql.cj.protocol.a.NativeSocketConnection.connect(NativeSocketConnection.java:89) ~[mysql-connector-java-8.0.30.jar:8.0.30]
	at com.mysql.cj.NativeSession.connect(NativeSession.java:120) ~[mysql-connector-java-8.0.30.jar:8.0.30]
	at com.mysql.cj.jdbc.ConnectionImpl.connectOneTryOnly(ConnectionImpl.java:948) ~[mysql-connector-java-8.0.30.jar:8.0.30]
	at com.mysql.cj.jdbc.ConnectionImpl.createNewIO(ConnectionImpl.java:818) ~[mysql-connector-java-8.0.30.jar:8.0.30]
	at com.mysql.cj.jdbc.ConnectionImpl.<init>(ConnectionImpl.java:448) ~[mysql-connector-java-8.0.30.jar:8.0.30]
	at com.mysql.cj.jdbc.ConnectionImpl.getInstance(ConnectionImpl.java:241) ~[mysql-connector-java-8.0.30.jar:8.0.30]
	at com.mysql.cj.jdbc.NonRegisteringDriver.connect(NonRegisteringDriver.java:198) ~[mysql-connector-java-8.0.30.jar:8.0.30]
	at com.zaxxer.hikari.util.DriverDataSource.getConnection(DriverDataSource.java:138) ~[HikariCP-4.0.3.jar:?]
	at com.zaxxer.hikari.pool.PoolBase.newConnection(PoolBase.java:364) ~[HikariCP-4.0.3.jar:?]
	at com.zaxxer.hikari.pool.PoolBase.newPoolEntry(PoolBase.java:206) ~[HikariCP-4.0.3.jar:?]
	at com.zaxxer.hikari.pool.HikariPool.createPoolEntry(HikariPool.java:476) ~[HikariCP-4.0.3.jar:?]
	at com.zaxxer.hikari.pool.HikariPool.access$100(HikariPool.java:71) ~[HikariCP-4.0.3.jar:?]
	at com.zaxxer.hikari.pool.HikariPool$PoolEntryCreator.call(HikariPool.java:726) ~[HikariCP-4.0.3.jar:?]
	at com.zaxxer.hikari.pool.HikariPool$PoolEntryCreator.call(HikariPool.java:712) ~[HikariCP-4.0.3.jar:?]
	at java.util.concurrent.FutureTask.run(FutureTask.java:264) ~[?:?]
	at java.util.concurrent.ThreadPoolExecutor.runWorker(ThreadPoolExecutor.java:1128) ~[?:?]
	at java.util.concurrent.ThreadPoolExecutor$Worker.run(ThreadPoolExecutor.java:628) ~[?:?]
	... 1 more
Caused by: java.net.UnknownHostException: No such host is known (freshersuperchargers.czbdrgtkozjs.us-east-1.rds.amazonaws.com)
	at java.net.Inet6AddressImpl.lookupAllHostAddr(Native Method) ~[?:?]
	at java.net.InetAddress$PlatformNameService.lookupAllHostAddr(InetAddress.java:929) ~[?:?]
	at java.net.InetAddress.getAddressesFromNameService(InetAddress.java:1538) ~[?:?]
	at java.net.InetAddress$NameServiceAddresses.get(InetAddress.java:848) ~[?:?]
	at java.net.InetAddress.getAllByName0(InetAddress.java:1527) ~[?:?]
	at java.net.InetAddress.getAllByName(InetAddress.java:1380) ~[?:?]
	at java.net.InetAddress.getAllByName(InetAddress.java:1302) ~[?:?]
	at com.mysql.cj.protocol.StandardSocketFactory.connect(StandardSocketFactory.java:130) ~[mysql-connector-java-8.0.30.jar:8.0.30]
	at com.mysql.cj.protocol.a.NativeSocketConnection.connect(NativeSocketConnection.java:63) ~[mysql-connector-java-8.0.30.jar:8.0.30]
	at com.mysql.cj.NativeSession.connect(NativeSession.java:120) ~[mysql-connector-java-8.0.30.jar:8.0.30]
	at com.mysql.cj.jdbc.ConnectionImpl.connectOneTryOnly(ConnectionImpl.java:948) ~[mysql-connector-java-8.0.30.jar:8.0.30]
	at com.mysql.cj.jdbc.ConnectionImpl.createNewIO(ConnectionImpl.java:818) ~[mysql-connector-java-8.0.30.jar:8.0.30]
	at com.mysql.cj.jdbc.ConnectionImpl.<init>(ConnectionImpl.java:448) ~[mysql-connector-java-8.0.30.jar:8.0.30]
	at com.mysql.cj.jdbc.ConnectionImpl.getInstance(ConnectionImpl.java:241) ~[mysql-connector-java-8.0.30.jar:8.0.30]
	at com.mysql.cj.jdbc.NonRegisteringDriver.connect(NonRegisteringDriver.java:198) ~[mysql-connector-java-8.0.30.jar:8.0.30]
	at com.zaxxer.hikari.util.DriverDataSource.getConnection(DriverDataSource.java:138) ~[HikariCP-4.0.3.jar:?]
	at com.zaxxer.hikari.pool.PoolBase.newConnection(PoolBase.java:364) ~[HikariCP-4.0.3.jar:?]
	at com.zaxxer.hikari.pool.PoolBase.newPoolEntry(PoolBase.java:206) ~[HikariCP-4.0.3.jar:?]
	at com.zaxxer.hikari.pool.HikariPool.createPoolEntry(HikariPool.java:476) ~[HikariCP-4.0.3.jar:?]
	at com.zaxxer.hikari.pool.HikariPool.access$100(HikariPool.java:71) ~[HikariCP-4.0.3.jar:?]
	at com.zaxxer.hikari.pool.HikariPool$PoolEntryCreator.call(HikariPool.java:726) ~[HikariCP-4.0.3.jar:?]
	at com.zaxxer.hikari.pool.HikariPool$PoolEntryCreator.call(HikariPool.java:712) ~[HikariCP-4.0.3.jar:?]
	at java.util.concurrent.FutureTask.run(FutureTask.java:264) ~[?:?]
	at java.util.concurrent.ThreadPoolExecutor.runWorker(ThreadPoolExecutor.java:1128) ~[?:?]
	at java.util.concurrent.ThreadPoolExecutor$Worker.run(ThreadPoolExecutor.java:628) ~[?:?]
	... 1 more
[2023-08-18 11:00:57,262] - [org.hibernate.engine.jdbc.spi.SqlExceptionHelper] [logExceptions] -> (WARN) [SQL Error: 0, SQLState: 08S01] 
[2023-08-18 11:00:57,262] - [org.hibernate.engine.jdbc.spi.SqlExceptionHelper] [logExceptions] -> (ERROR) [HikariPool-21 - Connection is not available, request timed out after 30002ms.] 
[2023-08-18 11:00:57,262] - [org.hibernate.engine.jdbc.spi.SqlExceptionHelper] [logExceptions] -> (ERROR) [Communications link failure

The last packet sent successfully to the server was 0 milliseconds ago. The driver has not received any packets from the server.] 
[2023-08-18 11:00:57,263] - [org.camunda.bpm.engine.jobexecutor] [logError] -> (ERROR) [ENGINE-14019 Exception during job acquisition Could not open JPA EntityManager for transaction; nested exception is org.hibernate.exception.JDBCConnectionException: Unable to acquire JDBC Connection] 
org.springframework.transaction.CannotCreateTransactionException: Could not open JPA EntityManager for transaction; nested exception is org.hibernate.exception.JDBCConnectionException: Unable to acquire JDBC Connection
	at org.springframework.orm.jpa.JpaTransactionManager.doBegin(JpaTransactionManager.java:467) ~[spring-orm-5.3.22.jar:5.3.22]
	at org.springframework.transaction.support.AbstractPlatformTransactionManager.startTransaction(AbstractPlatformTransactionManager.java:400) ~[spring-tx-5.3.22.jar:5.3.22]
	at org.springframework.transaction.support.AbstractPlatformTransactionManager.getTransaction(AbstractPlatformTransactionManager.java:373) ~[spring-tx-5.3.22.jar:5.3.22]
	at org.springframework.transaction.support.TransactionTemplate.execute(TransactionTemplate.java:137) ~[spring-tx-5.3.22.jar:5.3.22]
	at org.camunda.bpm.engine.spring.SpringTransactionInterceptor.execute(SpringTransactionInterceptor.java:71) ~[camunda-engine-spring-7.18.0.jar:7.18.0]
	at org.camunda.bpm.engine.impl.interceptor.ProcessApplicationContextInterceptor.execute(ProcessApplicationContextInterceptor.java:70) ~[camunda-engine-7.18.0.jar:7.18.0]
	at org.camunda.bpm.engine.impl.interceptor.CommandCounterInterceptor.execute(CommandCounterInterceptor.java:35) ~[camunda-engine-7.18.0.jar:7.18.0]
	at org.camunda.bpm.engine.impl.interceptor.LogInterceptor.execute(LogInterceptor.java:33) ~[camunda-engine-7.18.0.jar:7.18.0]
	at org.camunda.bpm.engine.impl.interceptor.ExceptionCodeInterceptor.execute(ExceptionCodeInterceptor.java:55) ~[camunda-engine-7.18.0.jar:7.18.0]
	at org.camunda.bpm.engine.impl.jobexecutor.SequentialJobAcquisitionRunnable.acquireJobs(SequentialJobAcquisitionRunnable.java:164) ~[camunda-engine-7.18.0.jar:7.18.0]
	at org.camunda.bpm.engine.impl.jobexecutor.SequentialJobAcquisitionRunnable.run(SequentialJobAcquisitionRunnable.java:80) ~[camunda-engine-7.18.0.jar:7.18.0]
	at java.lang.Thread.run(Thread.java:834) ~[?:?]
Caused by: org.hibernate.exception.JDBCConnectionException: Unable to acquire JDBC Connection
	at org.hibernate.exception.internal.SQLExceptionTypeDelegate.convert(SQLExceptionTypeDelegate.java:48) ~[hibernate-core-5.6.11.Final.jar:5.6.11.Final]
	at org.hibernate.exception.internal.StandardSQLExceptionConverter.convert(StandardSQLExceptionConverter.java:37) ~[hibernate-core-5.6.11.Final.jar:5.6.11.Final]
	at org.hibernate.engine.jdbc.spi.SqlExceptionHelper.convert(SqlExceptionHelper.java:113) ~[hibernate-core-5.6.11.Final.jar:5.6.11.Final]
	at org.hibernate.engine.jdbc.spi.SqlExceptionHelper.convert(SqlExceptionHelper.java:99) ~[hibernate-core-5.6.11.Final.jar:5.6.11.Final]
	at org.hibernate.resource.jdbc.internal.LogicalConnectionManagedImpl.acquireConnectionIfNeeded(LogicalConnectionManagedImpl.java:111) ~[hibernate-core-5.6.11.Final.jar:5.6.11.Final]
	at org.hibernate.resource.jdbc.internal.LogicalConnectionManagedImpl.getPhysicalConnection(LogicalConnectionManagedImpl.java:138) ~[hibernate-core-5.6.11.Final.jar:5.6.11.Final]
	at org.hibernate.resource.jdbc.internal.LogicalConnectionManagedImpl.getConnectionForTransactionManagement(LogicalConnectionManagedImpl.java:276) ~[hibernate-core-5.6.11.Final.jar:5.6.11.Final]
	at org.hibernate.resource.jdbc.internal.LogicalConnectionManagedImpl.begin(LogicalConnectionManagedImpl.java:284) ~[hibernate-core-5.6.11.Final.jar:5.6.11.Final]
	at org.hibernate.resource.transaction.backend.jdbc.internal.JdbcResourceLocalTransactionCoordinatorImpl$TransactionDriverControlImpl.begin(JdbcResourceLocalTransactionCoordinatorImpl.java:246) ~[hibernate-core-5.6.11.Final.jar:5.6.11.Final]
	at org.hibernate.engine.transaction.internal.TransactionImpl.begin(TransactionImpl.java:83) ~[hibernate-core-5.6.11.Final.jar:5.6.11.Final]
	at org.springframework.orm.jpa.vendor.HibernateJpaDialect.beginTransaction(HibernateJpaDialect.java:164) ~[spring-orm-5.3.22.jar:5.3.22]
	at org.springframework.orm.jpa.JpaTransactionManager.doBegin(JpaTransactionManager.java:421) ~[spring-orm-5.3.22.jar:5.3.22]
	... 11 more
Caused by: java.sql.SQLTransientConnectionException: HikariPool-21 - Connection is not available, request timed out after 30002ms.
	at com.zaxxer.hikari.pool.HikariPool.createTimeoutException(HikariPool.java:696) ~[HikariCP-4.0.3.jar:?]
	at com.zaxxer.hikari.pool.HikariPool.getConnection(HikariPool.java:197) ~[HikariCP-4.0.3.jar:?]
	at com.zaxxer.hikari.pool.HikariPool.getConnection(HikariPool.java:162) ~[HikariCP-4.0.3.jar:?]
	at com.zaxxer.hikari.HikariDataSource.getConnection(HikariDataSource.java:128) ~[HikariCP-4.0.3.jar:?]
	at org.hibernate.engine.jdbc.connections.internal.DatasourceConnectionProviderImpl.getConnection(DatasourceConnectionProviderImpl.java:122) ~[hibernate-core-5.6.11.Final.jar:5.6.11.Final]
	at org.hibernate.internal.NonContextualJdbcConnectionAccess.obtainConnection(NonContextualJdbcConnectionAccess.java:38) ~[hibernate-core-5.6.11.Final.jar:5.6.11.Final]
	at org.hibernate.resource.jdbc.internal.LogicalConnectionManagedImpl.acquireConnectionIfNeeded(LogicalConnectionManagedImpl.java:108) ~[hibernate-core-5.6.11.Final.jar:5.6.11.Final]
	at org.hibernate.resource.jdbc.internal.LogicalConnectionManagedImpl.getPhysicalConnection(LogicalConnectionManagedImpl.java:138) ~[hibernate-core-5.6.11.Final.jar:5.6.11.Final]
	at org.hibernate.resource.jdbc.internal.LogicalConnectionManagedImpl.getConnectionForTransactionManagement(LogicalConnectionManagedImpl.java:276) ~[hibernate-core-5.6.11.Final.jar:5.6.11.Final]
	at org.hibernate.resource.jdbc.internal.LogicalConnectionManagedImpl.begin(LogicalConnectionManagedImpl.java:284) ~[hibernate-core-5.6.11.Final.jar:5.6.11.Final]
	at org.hibernate.resource.transaction.backend.jdbc.internal.JdbcResourceLocalTransactionCoordinatorImpl$TransactionDriverControlImpl.begin(JdbcResourceLocalTransactionCoordinatorImpl.java:246) ~[hibernate-core-5.6.11.Final.jar:5.6.11.Final]
	at org.hibernate.engine.transaction.internal.TransactionImpl.begin(TransactionImpl.java:83) ~[hibernate-core-5.6.11.Final.jar:5.6.11.Final]
	at org.springframework.orm.jpa.vendor.HibernateJpaDialect.beginTransaction(HibernateJpaDialect.java:164) ~[spring-orm-5.3.22.jar:5.3.22]
	at org.springframework.orm.jpa.JpaTransactionManager.doBegin(JpaTransactionManager.java:421) ~[spring-orm-5.3.22.jar:5.3.22]
	... 11 more
Caused by: com.mysql.cj.jdbc.exceptions.CommunicationsException: Communications link failure

The last packet sent successfully to the server was 0 milliseconds ago. The driver has not received any packets from the server.
	at com.mysql.cj.jdbc.exceptions.SQLError.createCommunicationsException(SQLError.java:174) ~[mysql-connector-java-8.0.30.jar:8.0.30]
	at com.mysql.cj.jdbc.exceptions.SQLExceptionsMapping.translateException(SQLExceptionsMapping.java:64) ~[mysql-connector-java-8.0.30.jar:8.0.30]
	at com.mysql.cj.jdbc.ConnectionImpl.createNewIO(ConnectionImpl.java:828) ~[mysql-connector-java-8.0.30.jar:8.0.30]
	at com.mysql.cj.jdbc.ConnectionImpl.<init>(ConnectionImpl.java:448) ~[mysql-connector-java-8.0.30.jar:8.0.30]
	at com.mysql.cj.jdbc.ConnectionImpl.getInstance(ConnectionImpl.java:241) ~[mysql-connector-java-8.0.30.jar:8.0.30]
	at com.mysql.cj.jdbc.NonRegisteringDriver.connect(NonRegisteringDriver.java:198) ~[mysql-connector-java-8.0.30.jar:8.0.30]
	at com.zaxxer.hikari.util.DriverDataSource.getConnection(DriverDataSource.java:138) ~[HikariCP-4.0.3.jar:?]
	at com.zaxxer.hikari.pool.PoolBase.newConnection(PoolBase.java:364) ~[HikariCP-4.0.3.jar:?]
	at com.zaxxer.hikari.pool.PoolBase.newPoolEntry(PoolBase.java:206) ~[HikariCP-4.0.3.jar:?]
	at com.zaxxer.hikari.pool.HikariPool.createPoolEntry(HikariPool.java:476) ~[HikariCP-4.0.3.jar:?]
	at com.zaxxer.hikari.pool.HikariPool.access$100(HikariPool.java:71) ~[HikariCP-4.0.3.jar:?]
	at com.zaxxer.hikari.pool.HikariPool$PoolEntryCreator.call(HikariPool.java:726) ~[HikariCP-4.0.3.jar:?]
	at com.zaxxer.hikari.pool.HikariPool$PoolEntryCreator.call(HikariPool.java:712) ~[HikariCP-4.0.3.jar:?]
	at java.util.concurrent.FutureTask.run(FutureTask.java:264) ~[?:?]
	at java.util.concurrent.ThreadPoolExecutor.runWorker(ThreadPoolExecutor.java:1128) ~[?:?]
	at java.util.concurrent.ThreadPoolExecutor$Worker.run(ThreadPoolExecutor.java:628) ~[?:?]
	... 1 more
Caused by: com.mysql.cj.exceptions.CJCommunicationsException: Communications link failure

The last packet sent successfully to the server was 0 milliseconds ago. The driver has not received any packets from the server.
	at jdk.internal.reflect.GeneratedConstructorAccessor491.newInstance(Unknown Source) ~[?:?]
	at jdk.internal.reflect.DelegatingConstructorAccessorImpl.newInstance(DelegatingConstructorAccessorImpl.java:45) ~[?:?]
	at java.lang.reflect.Constructor.newInstance(Constructor.java:490) ~[?:?]
	at com.mysql.cj.exceptions.ExceptionFactory.createException(ExceptionFactory.java:61) ~[mysql-connector-java-8.0.30.jar:8.0.30]
	at com.mysql.cj.exceptions.ExceptionFactory.createException(ExceptionFactory.java:105) ~[mysql-connector-java-8.0.30.jar:8.0.30]
	at com.mysql.cj.exceptions.ExceptionFactory.createException(ExceptionFactory.java:151) ~[mysql-connector-java-8.0.30.jar:8.0.30]
	at com.mysql.cj.exceptions.ExceptionFactory.createCommunicationsException(ExceptionFactory.java:167) ~[mysql-connector-java-8.0.30.jar:8.0.30]
	at com.mysql.cj.protocol.a.NativeSocketConnection.connect(NativeSocketConnection.java:89) ~[mysql-connector-java-8.0.30.jar:8.0.30]
	at com.mysql.cj.NativeSession.connect(NativeSession.java:120) ~[mysql-connector-java-8.0.30.jar:8.0.30]
	at com.mysql.cj.jdbc.ConnectionImpl.connectOneTryOnly(ConnectionImpl.java:948) ~[mysql-connector-java-8.0.30.jar:8.0.30]
	at com.mysql.cj.jdbc.ConnectionImpl.createNewIO(ConnectionImpl.java:818) ~[mysql-connector-java-8.0.30.jar:8.0.30]
	at com.mysql.cj.jdbc.ConnectionImpl.<init>(ConnectionImpl.java:448) ~[mysql-connector-java-8.0.30.jar:8.0.30]
	at com.mysql.cj.jdbc.ConnectionImpl.getInstance(ConnectionImpl.java:241) ~[mysql-connector-java-8.0.30.jar:8.0.30]
	at com.mysql.cj.jdbc.NonRegisteringDriver.connect(NonRegisteringDriver.java:198) ~[mysql-connector-java-8.0.30.jar:8.0.30]
	at com.zaxxer.hikari.util.DriverDataSource.getConnection(DriverDataSource.java:138) ~[HikariCP-4.0.3.jar:?]
	at com.zaxxer.hikari.pool.PoolBase.newConnection(PoolBase.java:364) ~[HikariCP-4.0.3.jar:?]
	at com.zaxxer.hikari.pool.PoolBase.newPoolEntry(PoolBase.java:206) ~[HikariCP-4.0.3.jar:?]
	at com.zaxxer.hikari.pool.HikariPool.createPoolEntry(HikariPool.java:476) ~[HikariCP-4.0.3.jar:?]
	at com.zaxxer.hikari.pool.HikariPool.access$100(HikariPool.java:71) ~[HikariCP-4.0.3.jar:?]
	at com.zaxxer.hikari.pool.HikariPool$PoolEntryCreator.call(HikariPool.java:726) ~[HikariCP-4.0.3.jar:?]
	at com.zaxxer.hikari.pool.HikariPool$PoolEntryCreator.call(HikariPool.java:712) ~[HikariCP-4.0.3.jar:?]
	at java.util.concurrent.FutureTask.run(FutureTask.java:264) ~[?:?]
	at java.util.concurrent.ThreadPoolExecutor.runWorker(ThreadPoolExecutor.java:1128) ~[?:?]
	at java.util.concurrent.ThreadPoolExecutor$Worker.run(ThreadPoolExecutor.java:628) ~[?:?]
	... 1 more
Caused by: java.net.UnknownHostException: No such host is known (freshersuperchargers.czbdrgtkozjs.us-east-1.rds.amazonaws.com)
	at java.net.Inet6AddressImpl.lookupAllHostAddr(Native Method) ~[?:?]
	at java.net.InetAddress$PlatformNameService.lookupAllHostAddr(InetAddress.java:929) ~[?:?]
	at java.net.InetAddress.getAddressesFromNameService(InetAddress.java:1538) ~[?:?]
	at java.net.InetAddress$NameServiceAddresses.get(InetAddress.java:848) ~[?:?]
	at java.net.InetAddress.getAllByName0(InetAddress.java:1527) ~[?:?]
	at java.net.InetAddress.getAllByName(InetAddress.java:1380) ~[?:?]
	at java.net.InetAddress.getAllByName(InetAddress.java:1302) ~[?:?]
	at com.mysql.cj.protocol.StandardSocketFactory.connect(StandardSocketFactory.java:130) ~[mysql-connector-java-8.0.30.jar:8.0.30]
	at com.mysql.cj.protocol.a.NativeSocketConnection.connect(NativeSocketConnection.java:63) ~[mysql-connector-java-8.0.30.jar:8.0.30]
	at com.mysql.cj.NativeSession.connect(NativeSession.java:120) ~[mysql-connector-java-8.0.30.jar:8.0.30]
	at com.mysql.cj.jdbc.ConnectionImpl.connectOneTryOnly(ConnectionImpl.java:948) ~[mysql-connector-java-8.0.30.jar:8.0.30]
	at com.mysql.cj.jdbc.ConnectionImpl.createNewIO(ConnectionImpl.java:818) ~[mysql-connector-java-8.0.30.jar:8.0.30]
	at com.mysql.cj.jdbc.ConnectionImpl.<init>(ConnectionImpl.java:448) ~[mysql-connector-java-8.0.30.jar:8.0.30]
	at com.mysql.cj.jdbc.ConnectionImpl.getInstance(ConnectionImpl.java:241) ~[mysql-connector-java-8.0.30.jar:8.0.30]
	at com.mysql.cj.jdbc.NonRegisteringDriver.connect(NonRegisteringDriver.java:198) ~[mysql-connector-java-8.0.30.jar:8.0.30]
	at com.zaxxer.hikari.util.DriverDataSource.getConnection(DriverDataSource.java:138) ~[HikariCP-4.0.3.jar:?]
	at com.zaxxer.hikari.pool.PoolBase.newConnection(PoolBase.java:364) ~[HikariCP-4.0.3.jar:?]
	at com.zaxxer.hikari.pool.PoolBase.newPoolEntry(PoolBase.java:206) ~[HikariCP-4.0.3.jar:?]
	at com.zaxxer.hikari.pool.HikariPool.createPoolEntry(HikariPool.java:476) ~[HikariCP-4.0.3.jar:?]
	at com.zaxxer.hikari.pool.HikariPool.access$100(HikariPool.java:71) ~[HikariCP-4.0.3.jar:?]
	at com.zaxxer.hikari.pool.HikariPool$PoolEntryCreator.call(HikariPool.java:726) ~[HikariCP-4.0.3.jar:?]
	at com.zaxxer.hikari.pool.HikariPool$PoolEntryCreator.call(HikariPool.java:712) ~[HikariCP-4.0.3.jar:?]
	at java.util.concurrent.FutureTask.run(FutureTask.java:264) ~[?:?]
	at java.util.concurrent.ThreadPoolExecutor.runWorker(ThreadPoolExecutor.java:1128) ~[?:?]
	at java.util.concurrent.ThreadPoolExecutor$Worker.run(ThreadPoolExecutor.java:628) ~[?:?]
	... 1 more
[2023-08-18 11:01:57,268] - [org.hibernate.engine.jdbc.spi.SqlExceptionHelper] [logExceptions] -> (WARN) [SQL Error: 0, SQLState: 08S01] 
[2023-08-18 11:01:57,268] - [org.hibernate.engine.jdbc.spi.SqlExceptionHelper] [logExceptions] -> (ERROR) [HikariPool-21 - Connection is not available, request timed out after 30008ms.] 
[2023-08-18 11:01:57,268] - [org.hibernate.engine.jdbc.spi.SqlExceptionHelper] [logExceptions] -> (ERROR) [Communications link failure

The last packet sent successfully to the server was 0 milliseconds ago. The driver has not received any packets from the server.] 
[2023-08-18 11:01:57,269] - [org.camunda.bpm.engine.jobexecutor] [logError] -> (ERROR) [ENGINE-14019 Exception during job acquisition Could not open JPA EntityManager for transaction; nested exception is org.hibernate.exception.JDBCConnectionException: Unable to acquire JDBC Connection] 
org.springframework.transaction.CannotCreateTransactionException: Could not open JPA EntityManager for transaction; nested exception is org.hibernate.exception.JDBCConnectionException: Unable to acquire JDBC Connection
	at org.springframework.orm.jpa.JpaTransactionManager.doBegin(JpaTransactionManager.java:467) ~[spring-orm-5.3.22.jar:5.3.22]
	at org.springframework.transaction.support.AbstractPlatformTransactionManager.startTransaction(AbstractPlatformTransactionManager.java:400) ~[spring-tx-5.3.22.jar:5.3.22]
	at org.springframework.transaction.support.AbstractPlatformTransactionManager.getTransaction(AbstractPlatformTransactionManager.java:373) ~[spring-tx-5.3.22.jar:5.3.22]
	at org.springframework.transaction.support.TransactionTemplate.execute(TransactionTemplate.java:137) ~[spring-tx-5.3.22.jar:5.3.22]
	at org.camunda.bpm.engine.spring.SpringTransactionInterceptor.execute(SpringTransactionInterceptor.java:71) ~[camunda-engine-spring-7.18.0.jar:7.18.0]
	at org.camunda.bpm.engine.impl.interceptor.ProcessApplicationContextInterceptor.execute(ProcessApplicationContextInterceptor.java:70) ~[camunda-engine-7.18.0.jar:7.18.0]
	at org.camunda.bpm.engine.impl.interceptor.CommandCounterInterceptor.execute(CommandCounterInterceptor.java:35) ~[camunda-engine-7.18.0.jar:7.18.0]
	at org.camunda.bpm.engine.impl.interceptor.LogInterceptor.execute(LogInterceptor.java:33) ~[camunda-engine-7.18.0.jar:7.18.0]
	at org.camunda.bpm.engine.impl.interceptor.ExceptionCodeInterceptor.execute(ExceptionCodeInterceptor.java:55) ~[camunda-engine-7.18.0.jar:7.18.0]
	at org.camunda.bpm.engine.impl.jobexecutor.SequentialJobAcquisitionRunnable.acquireJobs(SequentialJobAcquisitionRunnable.java:164) ~[camunda-engine-7.18.0.jar:7.18.0]
	at org.camunda.bpm.engine.impl.jobexecutor.SequentialJobAcquisitionRunnable.run(SequentialJobAcquisitionRunnable.java:80) ~[camunda-engine-7.18.0.jar:7.18.0]
	at java.lang.Thread.run(Thread.java:834) ~[?:?]
Caused by: org.hibernate.exception.JDBCConnectionException: Unable to acquire JDBC Connection
	at org.hibernate.exception.internal.SQLExceptionTypeDelegate.convert(SQLExceptionTypeDelegate.java:48) ~[hibernate-core-5.6.11.Final.jar:5.6.11.Final]
	at org.hibernate.exception.internal.StandardSQLExceptionConverter.convert(StandardSQLExceptionConverter.java:37) ~[hibernate-core-5.6.11.Final.jar:5.6.11.Final]
	at org.hibernate.engine.jdbc.spi.SqlExceptionHelper.convert(SqlExceptionHelper.java:113) ~[hibernate-core-5.6.11.Final.jar:5.6.11.Final]
	at org.hibernate.engine.jdbc.spi.SqlExceptionHelper.convert(SqlExceptionHelper.java:99) ~[hibernate-core-5.6.11.Final.jar:5.6.11.Final]
	at org.hibernate.resource.jdbc.internal.LogicalConnectionManagedImpl.acquireConnectionIfNeeded(LogicalConnectionManagedImpl.java:111) ~[hibernate-core-5.6.11.Final.jar:5.6.11.Final]
	at org.hibernate.resource.jdbc.internal.LogicalConnectionManagedImpl.getPhysicalConnection(LogicalConnectionManagedImpl.java:138) ~[hibernate-core-5.6.11.Final.jar:5.6.11.Final]
	at org.hibernate.resource.jdbc.internal.LogicalConnectionManagedImpl.getConnectionForTransactionManagement(LogicalConnectionManagedImpl.java:276) ~[hibernate-core-5.6.11.Final.jar:5.6.11.Final]
	at org.hibernate.resource.jdbc.internal.LogicalConnectionManagedImpl.begin(LogicalConnectionManagedImpl.java:284) ~[hibernate-core-5.6.11.Final.jar:5.6.11.Final]
	at org.hibernate.resource.transaction.backend.jdbc.internal.JdbcResourceLocalTransactionCoordinatorImpl$TransactionDriverControlImpl.begin(JdbcResourceLocalTransactionCoordinatorImpl.java:246) ~[hibernate-core-5.6.11.Final.jar:5.6.11.Final]
	at org.hibernate.engine.transaction.internal.TransactionImpl.begin(TransactionImpl.java:83) ~[hibernate-core-5.6.11.Final.jar:5.6.11.Final]
	at org.springframework.orm.jpa.vendor.HibernateJpaDialect.beginTransaction(HibernateJpaDialect.java:164) ~[spring-orm-5.3.22.jar:5.3.22]
	at org.springframework.orm.jpa.JpaTransactionManager.doBegin(JpaTransactionManager.java:421) ~[spring-orm-5.3.22.jar:5.3.22]
	... 11 more
Caused by: java.sql.SQLTransientConnectionException: HikariPool-21 - Connection is not available, request timed out after 30008ms.
	at com.zaxxer.hikari.pool.HikariPool.createTimeoutException(HikariPool.java:696) ~[HikariCP-4.0.3.jar:?]
	at com.zaxxer.hikari.pool.HikariPool.getConnection(HikariPool.java:197) ~[HikariCP-4.0.3.jar:?]
	at com.zaxxer.hikari.pool.HikariPool.getConnection(HikariPool.java:162) ~[HikariCP-4.0.3.jar:?]
	at com.zaxxer.hikari.HikariDataSource.getConnection(HikariDataSource.java:128) ~[HikariCP-4.0.3.jar:?]
	at org.hibernate.engine.jdbc.connections.internal.DatasourceConnectionProviderImpl.getConnection(DatasourceConnectionProviderImpl.java:122) ~[hibernate-core-5.6.11.Final.jar:5.6.11.Final]
	at org.hibernate.internal.NonContextualJdbcConnectionAccess.obtainConnection(NonContextualJdbcConnectionAccess.java:38) ~[hibernate-core-5.6.11.Final.jar:5.6.11.Final]
	at org.hibernate.resource.jdbc.internal.LogicalConnectionManagedImpl.acquireConnectionIfNeeded(LogicalConnectionManagedImpl.java:108) ~[hibernate-core-5.6.11.Final.jar:5.6.11.Final]
	at org.hibernate.resource.jdbc.internal.LogicalConnectionManagedImpl.getPhysicalConnection(LogicalConnectionManagedImpl.java:138) ~[hibernate-core-5.6.11.Final.jar:5.6.11.Final]
	at org.hibernate.resource.jdbc.internal.LogicalConnectionManagedImpl.getConnectionForTransactionManagement(LogicalConnectionManagedImpl.java:276) ~[hibernate-core-5.6.11.Final.jar:5.6.11.Final]
	at org.hibernate.resource.jdbc.internal.LogicalConnectionManagedImpl.begin(LogicalConnectionManagedImpl.java:284) ~[hibernate-core-5.6.11.Final.jar:5.6.11.Final]
	at org.hibernate.resource.transaction.backend.jdbc.internal.JdbcResourceLocalTransactionCoordinatorImpl$TransactionDriverControlImpl.begin(JdbcResourceLocalTransactionCoordinatorImpl.java:246) ~[hibernate-core-5.6.11.Final.jar:5.6.11.Final]
	at org.hibernate.engine.transaction.internal.TransactionImpl.begin(TransactionImpl.java:83) ~[hibernate-core-5.6.11.Final.jar:5.6.11.Final]
	at org.springframework.orm.jpa.vendor.HibernateJpaDialect.beginTransaction(HibernateJpaDialect.java:164) ~[spring-orm-5.3.22.jar:5.3.22]
	at org.springframework.orm.jpa.JpaTransactionManager.doBegin(JpaTransactionManager.java:421) ~[spring-orm-5.3.22.jar:5.3.22]
	... 11 more
Caused by: com.mysql.cj.jdbc.exceptions.CommunicationsException: Communications link failure

The last packet sent successfully to the server was 0 milliseconds ago. The driver has not received any packets from the server.
	at com.mysql.cj.jdbc.exceptions.SQLError.createCommunicationsException(SQLError.java:174) ~[mysql-connector-java-8.0.30.jar:8.0.30]
	at com.mysql.cj.jdbc.exceptions.SQLExceptionsMapping.translateException(SQLExceptionsMapping.java:64) ~[mysql-connector-java-8.0.30.jar:8.0.30]
	at com.mysql.cj.jdbc.ConnectionImpl.createNewIO(ConnectionImpl.java:828) ~[mysql-connector-java-8.0.30.jar:8.0.30]
	at com.mysql.cj.jdbc.ConnectionImpl.<init>(ConnectionImpl.java:448) ~[mysql-connector-java-8.0.30.jar:8.0.30]
	at com.mysql.cj.jdbc.ConnectionImpl.getInstance(ConnectionImpl.java:241) ~[mysql-connector-java-8.0.30.jar:8.0.30]
	at com.mysql.cj.jdbc.NonRegisteringDriver.connect(NonRegisteringDriver.java:198) ~[mysql-connector-java-8.0.30.jar:8.0.30]
	at com.zaxxer.hikari.util.DriverDataSource.getConnection(DriverDataSource.java:138) ~[HikariCP-4.0.3.jar:?]
	at com.zaxxer.hikari.pool.PoolBase.newConnection(PoolBase.java:364) ~[HikariCP-4.0.3.jar:?]
	at com.zaxxer.hikari.pool.PoolBase.newPoolEntry(PoolBase.java:206) ~[HikariCP-4.0.3.jar:?]
	at com.zaxxer.hikari.pool.HikariPool.createPoolEntry(HikariPool.java:476) ~[HikariCP-4.0.3.jar:?]
	at com.zaxxer.hikari.pool.HikariPool.access$100(HikariPool.java:71) ~[HikariCP-4.0.3.jar:?]
	at com.zaxxer.hikari.pool.HikariPool$PoolEntryCreator.call(HikariPool.java:726) ~[HikariCP-4.0.3.jar:?]
	at com.zaxxer.hikari.pool.HikariPool$PoolEntryCreator.call(HikariPool.java:712) ~[HikariCP-4.0.3.jar:?]
	at java.util.concurrent.FutureTask.run(FutureTask.java:264) ~[?:?]
	at java.util.concurrent.ThreadPoolExecutor.runWorker(ThreadPoolExecutor.java:1128) ~[?:?]
	at java.util.concurrent.ThreadPoolExecutor$Worker.run(ThreadPoolExecutor.java:628) ~[?:?]
	... 1 more
Caused by: com.mysql.cj.exceptions.CJCommunicationsException: Communications link failure

The last packet sent successfully to the server was 0 milliseconds ago. The driver has not received any packets from the server.
	at jdk.internal.reflect.GeneratedConstructorAccessor491.newInstance(Unknown Source) ~[?:?]
	at jdk.internal.reflect.DelegatingConstructorAccessorImpl.newInstance(DelegatingConstructorAccessorImpl.java:45) ~[?:?]
	at java.lang.reflect.Constructor.newInstance(Constructor.java:490) ~[?:?]
	at com.mysql.cj.exceptions.ExceptionFactory.createException(ExceptionFactory.java:61) ~[mysql-connector-java-8.0.30.jar:8.0.30]
	at com.mysql.cj.exceptions.ExceptionFactory.createException(ExceptionFactory.java:105) ~[mysql-connector-java-8.0.30.jar:8.0.30]
	at com.mysql.cj.exceptions.ExceptionFactory.createException(ExceptionFactory.java:151) ~[mysql-connector-java-8.0.30.jar:8.0.30]
	at com.mysql.cj.exceptions.ExceptionFactory.createCommunicationsException(ExceptionFactory.java:167) ~[mysql-connector-java-8.0.30.jar:8.0.30]
	at com.mysql.cj.protocol.a.NativeSocketConnection.connect(NativeSocketConnection.java:89) ~[mysql-connector-java-8.0.30.jar:8.0.30]
	at com.mysql.cj.NativeSession.connect(NativeSession.java:120) ~[mysql-connector-java-8.0.30.jar:8.0.30]
	at com.mysql.cj.jdbc.ConnectionImpl.connectOneTryOnly(ConnectionImpl.java:948) ~[mysql-connector-java-8.0.30.jar:8.0.30]
	at com.mysql.cj.jdbc.ConnectionImpl.createNewIO(ConnectionImpl.java:818) ~[mysql-connector-java-8.0.30.jar:8.0.30]
	at com.mysql.cj.jdbc.ConnectionImpl.<init>(ConnectionImpl.java:448) ~[mysql-connector-java-8.0.30.jar:8.0.30]
	at com.mysql.cj.jdbc.ConnectionImpl.getInstance(ConnectionImpl.java:241) ~[mysql-connector-java-8.0.30.jar:8.0.30]
	at com.mysql.cj.jdbc.NonRegisteringDriver.connect(NonRegisteringDriver.java:198) ~[mysql-connector-java-8.0.30.jar:8.0.30]
	at com.zaxxer.hikari.util.DriverDataSource.getConnection(DriverDataSource.java:138) ~[HikariCP-4.0.3.jar:?]
	at com.zaxxer.hikari.pool.PoolBase.newConnection(PoolBase.java:364) ~[HikariCP-4.0.3.jar:?]
	at com.zaxxer.hikari.pool.PoolBase.newPoolEntry(PoolBase.java:206) ~[HikariCP-4.0.3.jar:?]
	at com.zaxxer.hikari.pool.HikariPool.createPoolEntry(HikariPool.java:476) ~[HikariCP-4.0.3.jar:?]
	at com.zaxxer.hikari.pool.HikariPool.access$100(HikariPool.java:71) ~[HikariCP-4.0.3.jar:?]
	at com.zaxxer.hikari.pool.HikariPool$PoolEntryCreator.call(HikariPool.java:726) ~[HikariCP-4.0.3.jar:?]
	at com.zaxxer.hikari.pool.HikariPool$PoolEntryCreator.call(HikariPool.java:712) ~[HikariCP-4.0.3.jar:?]
	at java.util.concurrent.FutureTask.run(FutureTask.java:264) ~[?:?]
	at java.util.concurrent.ThreadPoolExecutor.runWorker(ThreadPoolExecutor.java:1128) ~[?:?]
	at java.util.concurrent.ThreadPoolExecutor$Worker.run(ThreadPoolExecutor.java:628) ~[?:?]
	... 1 more
Caused by: java.net.UnknownHostException: No such host is known (freshersuperchargers.czbdrgtkozjs.us-east-1.rds.amazonaws.com)
	at java.net.Inet6AddressImpl.lookupAllHostAddr(Native Method) ~[?:?]
	at java.net.InetAddress$PlatformNameService.lookupAllHostAddr(InetAddress.java:929) ~[?:?]
	at java.net.InetAddress.getAddressesFromNameService(InetAddress.java:1538) ~[?:?]
	at java.net.InetAddress$NameServiceAddresses.get(InetAddress.java:848) ~[?:?]
	at java.net.InetAddress.getAllByName0(InetAddress.java:1527) ~[?:?]
	at java.net.InetAddress.getAllByName(InetAddress.java:1380) ~[?:?]
	at java.net.InetAddress.getAllByName(InetAddress.java:1302) ~[?:?]
	at com.mysql.cj.protocol.StandardSocketFactory.connect(StandardSocketFactory.java:130) ~[mysql-connector-java-8.0.30.jar:8.0.30]
	at com.mysql.cj.protocol.a.NativeSocketConnection.connect(NativeSocketConnection.java:63) ~[mysql-connector-java-8.0.30.jar:8.0.30]
	at com.mysql.cj.NativeSession.connect(NativeSession.java:120) ~[mysql-connector-java-8.0.30.jar:8.0.30]
	at com.mysql.cj.jdbc.ConnectionImpl.connectOneTryOnly(ConnectionImpl.java:948) ~[mysql-connector-java-8.0.30.jar:8.0.30]
	at com.mysql.cj.jdbc.ConnectionImpl.createNewIO(ConnectionImpl.java:818) ~[mysql-connector-java-8.0.30.jar:8.0.30]
	at com.mysql.cj.jdbc.ConnectionImpl.<init>(ConnectionImpl.java:448) ~[mysql-connector-java-8.0.30.jar:8.0.30]
	at com.mysql.cj.jdbc.ConnectionImpl.getInstance(ConnectionImpl.java:241) ~[mysql-connector-java-8.0.30.jar:8.0.30]
	at com.mysql.cj.jdbc.NonRegisteringDriver.connect(NonRegisteringDriver.java:198) ~[mysql-connector-java-8.0.30.jar:8.0.30]
	at com.zaxxer.hikari.util.DriverDataSource.getConnection(DriverDataSource.java:138) ~[HikariCP-4.0.3.jar:?]
	at com.zaxxer.hikari.pool.PoolBase.newConnection(PoolBase.java:364) ~[HikariCP-4.0.3.jar:?]
	at com.zaxxer.hikari.pool.PoolBase.newPoolEntry(PoolBase.java:206) ~[HikariCP-4.0.3.jar:?]
	at com.zaxxer.hikari.pool.HikariPool.createPoolEntry(HikariPool.java:476) ~[HikariCP-4.0.3.jar:?]
	at com.zaxxer.hikari.pool.HikariPool.access$100(HikariPool.java:71) ~[HikariCP-4.0.3.jar:?]
	at com.zaxxer.hikari.pool.HikariPool$PoolEntryCreator.call(HikariPool.java:726) ~[HikariCP-4.0.3.jar:?]
	at com.zaxxer.hikari.pool.HikariPool$PoolEntryCreator.call(HikariPool.java:712) ~[HikariCP-4.0.3.jar:?]
	at java.util.concurrent.FutureTask.run(FutureTask.java:264) ~[?:?]
	at java.util.concurrent.ThreadPoolExecutor.runWorker(ThreadPoolExecutor.java:1128) ~[?:?]
	at java.util.concurrent.ThreadPoolExecutor$Worker.run(ThreadPoolExecutor.java:628) ~[?:?]
	... 1 more
[2023-08-18 11:02:53,648] - [org.hibernate.engine.jdbc.spi.SqlExceptionHelper] [logExceptions] -> (WARN) [SQL Error: 0, SQLState: 08S01] 
[2023-08-18 11:02:53,648] - [org.hibernate.engine.jdbc.spi.SqlExceptionHelper] [logExceptions] -> (ERROR) [HikariPool-21 - Connection is not available, request timed out after 30012ms.] 
[2023-08-18 11:02:53,648] - [org.hibernate.engine.jdbc.spi.SqlExceptionHelper] [logExceptions] -> (ERROR) [Communications link failure

The last packet sent successfully to the server was 0 milliseconds ago. The driver has not received any packets from the server.] 
[2023-08-18 11:02:53,649] - [org.camunda.bpm.engine.metrics] [logWarn] -> (WARN) [ENGINE-18001 Could not collect and log metrics] 
org.springframework.transaction.CannotCreateTransactionException: Could not open JPA EntityManager for transaction; nested exception is org.hibernate.exception.JDBCConnectionException: Unable to acquire JDBC Connection
	at org.springframework.orm.jpa.JpaTransactionManager.doBegin(JpaTransactionManager.java:467) ~[spring-orm-5.3.22.jar:5.3.22]
	at org.springframework.transaction.support.AbstractPlatformTransactionManager.startTransaction(AbstractPlatformTransactionManager.java:400) ~[spring-tx-5.3.22.jar:5.3.22]
	at org.springframework.transaction.support.AbstractPlatformTransactionManager.getTransaction(AbstractPlatformTransactionManager.java:373) ~[spring-tx-5.3.22.jar:5.3.22]
	at org.springframework.transaction.support.TransactionTemplate.execute(TransactionTemplate.java:137) ~[spring-tx-5.3.22.jar:5.3.22]
	at org.camunda.bpm.engine.spring.SpringTransactionInterceptor.execute(SpringTransactionInterceptor.java:71) ~[camunda-engine-spring-7.18.0.jar:7.18.0]
	at org.camunda.bpm.engine.impl.interceptor.ProcessApplicationContextInterceptor.execute(ProcessApplicationContextInterceptor.java:70) ~[camunda-engine-7.18.0.jar:7.18.0]
	at org.camunda.bpm.engine.impl.interceptor.CommandCounterInterceptor.execute(CommandCounterInterceptor.java:35) ~[camunda-engine-7.18.0.jar:7.18.0]
	at org.camunda.bpm.engine.impl.interceptor.LogInterceptor.execute(LogInterceptor.java:33) ~[camunda-engine-7.18.0.jar:7.18.0]
	at org.camunda.bpm.engine.impl.interceptor.ExceptionCodeInterceptor.execute(ExceptionCodeInterceptor.java:55) ~[camunda-engine-7.18.0.jar:7.18.0]
	at org.camunda.bpm.engine.impl.metrics.reporter.MetricsCollectionTask.collectMetrics(MetricsCollectionTask.java:76) ~[camunda-engine-7.18.0.jar:7.18.0]
	at org.camunda.bpm.engine.impl.metrics.reporter.MetricsCollectionTask.run(MetricsCollectionTask.java:53) ~[camunda-engine-7.18.0.jar:7.18.0]
	at java.util.TimerThread.mainLoop(Timer.java:556) ~[?:?]
	at java.util.TimerThread.run(Timer.java:506) ~[?:?]
Caused by: org.hibernate.exception.JDBCConnectionException: Unable to acquire JDBC Connection
	at org.hibernate.exception.internal.SQLExceptionTypeDelegate.convert(SQLExceptionTypeDelegate.java:48) ~[hibernate-core-5.6.11.Final.jar:5.6.11.Final]
	at org.hibernate.exception.internal.StandardSQLExceptionConverter.convert(StandardSQLExceptionConverter.java:37) ~[hibernate-core-5.6.11.Final.jar:5.6.11.Final]
	at org.hibernate.engine.jdbc.spi.SqlExceptionHelper.convert(SqlExceptionHelper.java:113) ~[hibernate-core-5.6.11.Final.jar:5.6.11.Final]
	at org.hibernate.engine.jdbc.spi.SqlExceptionHelper.convert(SqlExceptionHelper.java:99) ~[hibernate-core-5.6.11.Final.jar:5.6.11.Final]
	at org.hibernate.resource.jdbc.internal.LogicalConnectionManagedImpl.acquireConnectionIfNeeded(LogicalConnectionManagedImpl.java:111) ~[hibernate-core-5.6.11.Final.jar:5.6.11.Final]
	at org.hibernate.resource.jdbc.internal.LogicalConnectionManagedImpl.getPhysicalConnection(LogicalConnectionManagedImpl.java:138) ~[hibernate-core-5.6.11.Final.jar:5.6.11.Final]
	at org.hibernate.resource.jdbc.internal.LogicalConnectionManagedImpl.getConnectionForTransactionManagement(LogicalConnectionManagedImpl.java:276) ~[hibernate-core-5.6.11.Final.jar:5.6.11.Final]
	at org.hibernate.resource.jdbc.internal.LogicalConnectionManagedImpl.begin(LogicalConnectionManagedImpl.java:284) ~[hibernate-core-5.6.11.Final.jar:5.6.11.Final]
	at org.hibernate.resource.transaction.backend.jdbc.internal.JdbcResourceLocalTransactionCoordinatorImpl$TransactionDriverControlImpl.begin(JdbcResourceLocalTransactionCoordinatorImpl.java:246) ~[hibernate-core-5.6.11.Final.jar:5.6.11.Final]
	at org.hibernate.engine.transaction.internal.TransactionImpl.begin(TransactionImpl.java:83) ~[hibernate-core-5.6.11.Final.jar:5.6.11.Final]
	at org.springframework.orm.jpa.vendor.HibernateJpaDialect.beginTransaction(HibernateJpaDialect.java:164) ~[spring-orm-5.3.22.jar:5.3.22]
	at org.springframework.orm.jpa.JpaTransactionManager.doBegin(JpaTransactionManager.java:421) ~[spring-orm-5.3.22.jar:5.3.22]
	... 12 more
Caused by: java.sql.SQLTransientConnectionException: HikariPool-21 - Connection is not available, request timed out after 30012ms.
	at com.zaxxer.hikari.pool.HikariPool.createTimeoutException(HikariPool.java:696) ~[HikariCP-4.0.3.jar:?]
	at com.zaxxer.hikari.pool.HikariPool.getConnection(HikariPool.java:197) ~[HikariCP-4.0.3.jar:?]
	at com.zaxxer.hikari.pool.HikariPool.getConnection(HikariPool.java:162) ~[HikariCP-4.0.3.jar:?]
	at com.zaxxer.hikari.HikariDataSource.getConnection(HikariDataSource.java:128) ~[HikariCP-4.0.3.jar:?]
	at org.hibernate.engine.jdbc.connections.internal.DatasourceConnectionProviderImpl.getConnection(DatasourceConnectionProviderImpl.java:122) ~[hibernate-core-5.6.11.Final.jar:5.6.11.Final]
	at org.hibernate.internal.NonContextualJdbcConnectionAccess.obtainConnection(NonContextualJdbcConnectionAccess.java:38) ~[hibernate-core-5.6.11.Final.jar:5.6.11.Final]
	at org.hibernate.resource.jdbc.internal.LogicalConnectionManagedImpl.acquireConnectionIfNeeded(LogicalConnectionManagedImpl.java:108) ~[hibernate-core-5.6.11.Final.jar:5.6.11.Final]
	at org.hibernate.resource.jdbc.internal.LogicalConnectionManagedImpl.getPhysicalConnection(LogicalConnectionManagedImpl.java:138) ~[hibernate-core-5.6.11.Final.jar:5.6.11.Final]
	at org.hibernate.resource.jdbc.internal.LogicalConnectionManagedImpl.getConnectionForTransactionManagement(LogicalConnectionManagedImpl.java:276) ~[hibernate-core-5.6.11.Final.jar:5.6.11.Final]
	at org.hibernate.resource.jdbc.internal.LogicalConnectionManagedImpl.begin(LogicalConnectionManagedImpl.java:284) ~[hibernate-core-5.6.11.Final.jar:5.6.11.Final]
	at org.hibernate.resource.transaction.backend.jdbc.internal.JdbcResourceLocalTransactionCoordinatorImpl$TransactionDriverControlImpl.begin(JdbcResourceLocalTransactionCoordinatorImpl.java:246) ~[hibernate-core-5.6.11.Final.jar:5.6.11.Final]
	at org.hibernate.engine.transaction.internal.TransactionImpl.begin(TransactionImpl.java:83) ~[hibernate-core-5.6.11.Final.jar:5.6.11.Final]
	at org.springframework.orm.jpa.vendor.HibernateJpaDialect.beginTransaction(HibernateJpaDialect.java:164) ~[spring-orm-5.3.22.jar:5.3.22]
	at org.springframework.orm.jpa.JpaTransactionManager.doBegin(JpaTransactionManager.java:421) ~[spring-orm-5.3.22.jar:5.3.22]
	... 12 more
Caused by: com.mysql.cj.jdbc.exceptions.CommunicationsException: Communications link failure

The last packet sent successfully to the server was 0 milliseconds ago. The driver has not received any packets from the server.
	at com.mysql.cj.jdbc.exceptions.SQLError.createCommunicationsException(SQLError.java:174) ~[mysql-connector-java-8.0.30.jar:8.0.30]
	at com.mysql.cj.jdbc.exceptions.SQLExceptionsMapping.translateException(SQLExceptionsMapping.java:64) ~[mysql-connector-java-8.0.30.jar:8.0.30]
	at com.mysql.cj.jdbc.ConnectionImpl.createNewIO(ConnectionImpl.java:828) ~[mysql-connector-java-8.0.30.jar:8.0.30]
	at com.mysql.cj.jdbc.ConnectionImpl.<init>(ConnectionImpl.java:448) ~[mysql-connector-java-8.0.30.jar:8.0.30]
	at com.mysql.cj.jdbc.ConnectionImpl.getInstance(ConnectionImpl.java:241) ~[mysql-connector-java-8.0.30.jar:8.0.30]
	at com.mysql.cj.jdbc.NonRegisteringDriver.connect(NonRegisteringDriver.java:198) ~[mysql-connector-java-8.0.30.jar:8.0.30]
	at com.zaxxer.hikari.util.DriverDataSource.getConnection(DriverDataSource.java:138) ~[HikariCP-4.0.3.jar:?]
	at com.zaxxer.hikari.pool.PoolBase.newConnection(PoolBase.java:364) ~[HikariCP-4.0.3.jar:?]
	at com.zaxxer.hikari.pool.PoolBase.newPoolEntry(PoolBase.java:206) ~[HikariCP-4.0.3.jar:?]
	at com.zaxxer.hikari.pool.HikariPool.createPoolEntry(HikariPool.java:476) ~[HikariCP-4.0.3.jar:?]
	at com.zaxxer.hikari.pool.HikariPool.access$100(HikariPool.java:71) ~[HikariCP-4.0.3.jar:?]
	at com.zaxxer.hikari.pool.HikariPool$PoolEntryCreator.call(HikariPool.java:726) ~[HikariCP-4.0.3.jar:?]
	at com.zaxxer.hikari.pool.HikariPool$PoolEntryCreator.call(HikariPool.java:712) ~[HikariCP-4.0.3.jar:?]
	at java.util.concurrent.FutureTask.run(FutureTask.java:264) ~[?:?]
	at java.util.concurrent.ThreadPoolExecutor.runWorker(ThreadPoolExecutor.java:1128) ~[?:?]
	at java.util.concurrent.ThreadPoolExecutor$Worker.run(ThreadPoolExecutor.java:628) ~[?:?]
	at java.lang.Thread.run(Thread.java:834) ~[?:?]
Caused by: com.mysql.cj.exceptions.CJCommunicationsException: Communications link failure

The last packet sent successfully to the server was 0 milliseconds ago. The driver has not received any packets from the server.
	at jdk.internal.reflect.GeneratedConstructorAccessor491.newInstance(Unknown Source) ~[?:?]
	at jdk.internal.reflect.DelegatingConstructorAccessorImpl.newInstance(DelegatingConstructorAccessorImpl.java:45) ~[?:?]
	at java.lang.reflect.Constructor.newInstance(Constructor.java:490) ~[?:?]
	at com.mysql.cj.exceptions.ExceptionFactory.createException(ExceptionFactory.java:61) ~[mysql-connector-java-8.0.30.jar:8.0.30]
	at com.mysql.cj.exceptions.ExceptionFactory.createException(ExceptionFactory.java:105) ~[mysql-connector-java-8.0.30.jar:8.0.30]
	at com.mysql.cj.exceptions.ExceptionFactory.createException(ExceptionFactory.java:151) ~[mysql-connector-java-8.0.30.jar:8.0.30]
	at com.mysql.cj.exceptions.ExceptionFactory.createCommunicationsException(ExceptionFactory.java:167) ~[mysql-connector-java-8.0.30.jar:8.0.30]
	at com.mysql.cj.protocol.a.NativeSocketConnection.connect(NativeSocketConnection.java:89) ~[mysql-connector-java-8.0.30.jar:8.0.30]
	at com.mysql.cj.NativeSession.connect(NativeSession.java:120) ~[mysql-connector-java-8.0.30.jar:8.0.30]
	at com.mysql.cj.jdbc.ConnectionImpl.connectOneTryOnly(ConnectionImpl.java:948) ~[mysql-connector-java-8.0.30.jar:8.0.30]
	at com.mysql.cj.jdbc.ConnectionImpl.createNewIO(ConnectionImpl.java:818) ~[mysql-connector-java-8.0.30.jar:8.0.30]
	at com.mysql.cj.jdbc.ConnectionImpl.<init>(ConnectionImpl.java:448) ~[mysql-connector-java-8.0.30.jar:8.0.30]
	at com.mysql.cj.jdbc.ConnectionImpl.getInstance(ConnectionImpl.java:241) ~[mysql-connector-java-8.0.30.jar:8.0.30]
	at com.mysql.cj.jdbc.NonRegisteringDriver.connect(NonRegisteringDriver.java:198) ~[mysql-connector-java-8.0.30.jar:8.0.30]
	at com.zaxxer.hikari.util.DriverDataSource.getConnection(DriverDataSource.java:138) ~[HikariCP-4.0.3.jar:?]
	at com.zaxxer.hikari.pool.PoolBase.newConnection(PoolBase.java:364) ~[HikariCP-4.0.3.jar:?]
	at com.zaxxer.hikari.pool.PoolBase.newPoolEntry(PoolBase.java:206) ~[HikariCP-4.0.3.jar:?]
	at com.zaxxer.hikari.pool.HikariPool.createPoolEntry(HikariPool.java:476) ~[HikariCP-4.0.3.jar:?]
	at com.zaxxer.hikari.pool.HikariPool.access$100(HikariPool.java:71) ~[HikariCP-4.0.3.jar:?]
	at com.zaxxer.hikari.pool.HikariPool$PoolEntryCreator.call(HikariPool.java:726) ~[HikariCP-4.0.3.jar:?]
	at com.zaxxer.hikari.pool.HikariPool$PoolEntryCreator.call(HikariPool.java:712) ~[HikariCP-4.0.3.jar:?]
	at java.util.concurrent.FutureTask.run(FutureTask.java:264) ~[?:?]
	at java.util.concurrent.ThreadPoolExecutor.runWorker(ThreadPoolExecutor.java:1128) ~[?:?]
	at java.util.concurrent.ThreadPoolExecutor$Worker.run(ThreadPoolExecutor.java:628) ~[?:?]
	at java.lang.Thread.run(Thread.java:834) ~[?:?]
Caused by: java.net.UnknownHostException: No such host is known (freshersuperchargers.czbdrgtkozjs.us-east-1.rds.amazonaws.com)
	at java.net.Inet6AddressImpl.lookupAllHostAddr(Native Method) ~[?:?]
	at java.net.InetAddress$PlatformNameService.lookupAllHostAddr(InetAddress.java:929) ~[?:?]
	at java.net.InetAddress.getAddressesFromNameService(InetAddress.java:1538) ~[?:?]
	at java.net.InetAddress$NameServiceAddresses.get(InetAddress.java:848) ~[?:?]
	at java.net.InetAddress.getAllByName0(InetAddress.java:1527) ~[?:?]
	at java.net.InetAddress.getAllByName(InetAddress.java:1380) ~[?:?]
	at java.net.InetAddress.getAllByName(InetAddress.java:1302) ~[?:?]
	at com.mysql.cj.protocol.StandardSocketFactory.connect(StandardSocketFactory.java:130) ~[mysql-connector-java-8.0.30.jar:8.0.30]
	at com.mysql.cj.protocol.a.NativeSocketConnection.connect(NativeSocketConnection.java:63) ~[mysql-connector-java-8.0.30.jar:8.0.30]
	at com.mysql.cj.NativeSession.connect(NativeSession.java:120) ~[mysql-connector-java-8.0.30.jar:8.0.30]
	at com.mysql.cj.jdbc.ConnectionImpl.connectOneTryOnly(ConnectionImpl.java:948) ~[mysql-connector-java-8.0.30.jar:8.0.30]
	at com.mysql.cj.jdbc.ConnectionImpl.createNewIO(ConnectionImpl.java:818) ~[mysql-connector-java-8.0.30.jar:8.0.30]
	at com.mysql.cj.jdbc.ConnectionImpl.<init>(ConnectionImpl.java:448) ~[mysql-connector-java-8.0.30.jar:8.0.30]
	at com.mysql.cj.jdbc.ConnectionImpl.getInstance(ConnectionImpl.java:241) ~[mysql-connector-java-8.0.30.jar:8.0.30]
	at com.mysql.cj.jdbc.NonRegisteringDriver.connect(NonRegisteringDriver.java:198) ~[mysql-connector-java-8.0.30.jar:8.0.30]
	at com.zaxxer.hikari.util.DriverDataSource.getConnection(DriverDataSource.java:138) ~[HikariCP-4.0.3.jar:?]
	at com.zaxxer.hikari.pool.PoolBase.newConnection(PoolBase.java:364) ~[HikariCP-4.0.3.jar:?]
	at com.zaxxer.hikari.pool.PoolBase.newPoolEntry(PoolBase.java:206) ~[HikariCP-4.0.3.jar:?]
	at com.zaxxer.hikari.pool.HikariPool.createPoolEntry(HikariPool.java:476) ~[HikariCP-4.0.3.jar:?]
	at com.zaxxer.hikari.pool.HikariPool.access$100(HikariPool.java:71) ~[HikariCP-4.0.3.jar:?]
	at com.zaxxer.hikari.pool.HikariPool$PoolEntryCreator.call(HikariPool.java:726) ~[HikariCP-4.0.3.jar:?]
	at com.zaxxer.hikari.pool.HikariPool$PoolEntryCreator.call(HikariPool.java:712) ~[HikariCP-4.0.3.jar:?]
	at java.util.concurrent.FutureTask.run(FutureTask.java:264) ~[?:?]
	at java.util.concurrent.ThreadPoolExecutor.runWorker(ThreadPoolExecutor.java:1128) ~[?:?]
	at java.util.concurrent.ThreadPoolExecutor$Worker.run(ThreadPoolExecutor.java:628) ~[?:?]
	at java.lang.Thread.run(Thread.java:834) ~[?:?]
[2023-08-18 11:02:57,284] - [org.hibernate.engine.jdbc.spi.SqlExceptionHelper] [logExceptions] -> (WARN) [SQL Error: 0, SQLState: 08S01] 
[2023-08-18 11:02:57,285] - [org.hibernate.engine.jdbc.spi.SqlExceptionHelper] [logExceptions] -> (ERROR) [HikariPool-21 - Connection is not available, request timed out after 30011ms.] 
[2023-08-18 11:02:57,285] - [org.hibernate.engine.jdbc.spi.SqlExceptionHelper] [logExceptions] -> (ERROR) [Communications link failure

The last packet sent successfully to the server was 0 milliseconds ago. The driver has not received any packets from the server.] 
[2023-08-18 11:02:57,285] - [org.camunda.bpm.engine.jobexecutor] [logError] -> (ERROR) [ENGINE-14019 Exception during job acquisition Could not open JPA EntityManager for transaction; nested exception is org.hibernate.exception.JDBCConnectionException: Unable to acquire JDBC Connection] 
org.springframework.transaction.CannotCreateTransactionException: Could not open JPA EntityManager for transaction; nested exception is org.hibernate.exception.JDBCConnectionException: Unable to acquire JDBC Connection
	at org.springframework.orm.jpa.JpaTransactionManager.doBegin(JpaTransactionManager.java:467) ~[spring-orm-5.3.22.jar:5.3.22]
	at org.springframework.transaction.support.AbstractPlatformTransactionManager.startTransaction(AbstractPlatformTransactionManager.java:400) ~[spring-tx-5.3.22.jar:5.3.22]
	at org.springframework.transaction.support.AbstractPlatformTransactionManager.getTransaction(AbstractPlatformTransactionManager.java:373) ~[spring-tx-5.3.22.jar:5.3.22]
	at org.springframework.transaction.support.TransactionTemplate.execute(TransactionTemplate.java:137) ~[spring-tx-5.3.22.jar:5.3.22]
	at org.camunda.bpm.engine.spring.SpringTransactionInterceptor.execute(SpringTransactionInterceptor.java:71) ~[camunda-engine-spring-7.18.0.jar:7.18.0]
	at org.camunda.bpm.engine.impl.interceptor.ProcessApplicationContextInterceptor.execute(ProcessApplicationContextInterceptor.java:70) ~[camunda-engine-7.18.0.jar:7.18.0]
	at org.camunda.bpm.engine.impl.interceptor.CommandCounterInterceptor.execute(CommandCounterInterceptor.java:35) ~[camunda-engine-7.18.0.jar:7.18.0]
	at org.camunda.bpm.engine.impl.interceptor.LogInterceptor.execute(LogInterceptor.java:33) ~[camunda-engine-7.18.0.jar:7.18.0]
	at org.camunda.bpm.engine.impl.interceptor.ExceptionCodeInterceptor.execute(ExceptionCodeInterceptor.java:55) ~[camunda-engine-7.18.0.jar:7.18.0]
	at org.camunda.bpm.engine.impl.jobexecutor.SequentialJobAcquisitionRunnable.acquireJobs(SequentialJobAcquisitionRunnable.java:164) ~[camunda-engine-7.18.0.jar:7.18.0]
	at org.camunda.bpm.engine.impl.jobexecutor.SequentialJobAcquisitionRunnable.run(SequentialJobAcquisitionRunnable.java:80) ~[camunda-engine-7.18.0.jar:7.18.0]
	at java.lang.Thread.run(Thread.java:834) ~[?:?]
Caused by: org.hibernate.exception.JDBCConnectionException: Unable to acquire JDBC Connection
	at org.hibernate.exception.internal.SQLExceptionTypeDelegate.convert(SQLExceptionTypeDelegate.java:48) ~[hibernate-core-5.6.11.Final.jar:5.6.11.Final]
	at org.hibernate.exception.internal.StandardSQLExceptionConverter.convert(StandardSQLExceptionConverter.java:37) ~[hibernate-core-5.6.11.Final.jar:5.6.11.Final]
	at org.hibernate.engine.jdbc.spi.SqlExceptionHelper.convert(SqlExceptionHelper.java:113) ~[hibernate-core-5.6.11.Final.jar:5.6.11.Final]
	at org.hibernate.engine.jdbc.spi.SqlExceptionHelper.convert(SqlExceptionHelper.java:99) ~[hibernate-core-5.6.11.Final.jar:5.6.11.Final]
	at org.hibernate.resource.jdbc.internal.LogicalConnectionManagedImpl.acquireConnectionIfNeeded(LogicalConnectionManagedImpl.java:111) ~[hibernate-core-5.6.11.Final.jar:5.6.11.Final]
	at org.hibernate.resource.jdbc.internal.LogicalConnectionManagedImpl.getPhysicalConnection(LogicalConnectionManagedImpl.java:138) ~[hibernate-core-5.6.11.Final.jar:5.6.11.Final]
	at org.hibernate.resource.jdbc.internal.LogicalConnectionManagedImpl.getConnectionForTransactionManagement(LogicalConnectionManagedImpl.java:276) ~[hibernate-core-5.6.11.Final.jar:5.6.11.Final]
	at org.hibernate.resource.jdbc.internal.LogicalConnectionManagedImpl.begin(LogicalConnectionManagedImpl.java:284) ~[hibernate-core-5.6.11.Final.jar:5.6.11.Final]
	at org.hibernate.resource.transaction.backend.jdbc.internal.JdbcResourceLocalTransactionCoordinatorImpl$TransactionDriverControlImpl.begin(JdbcResourceLocalTransactionCoordinatorImpl.java:246) ~[hibernate-core-5.6.11.Final.jar:5.6.11.Final]
	at org.hibernate.engine.transaction.internal.TransactionImpl.begin(TransactionImpl.java:83) ~[hibernate-core-5.6.11.Final.jar:5.6.11.Final]
	at org.springframework.orm.jpa.vendor.HibernateJpaDialect.beginTransaction(HibernateJpaDialect.java:164) ~[spring-orm-5.3.22.jar:5.3.22]
	at org.springframework.orm.jpa.JpaTransactionManager.doBegin(JpaTransactionManager.java:421) ~[spring-orm-5.3.22.jar:5.3.22]
	... 11 more
Caused by: java.sql.SQLTransientConnectionException: HikariPool-21 - Connection is not available, request timed out after 30011ms.
	at com.zaxxer.hikari.pool.HikariPool.createTimeoutException(HikariPool.java:696) ~[HikariCP-4.0.3.jar:?]
	at com.zaxxer.hikari.pool.HikariPool.getConnection(HikariPool.java:197) ~[HikariCP-4.0.3.jar:?]
	at com.zaxxer.hikari.pool.HikariPool.getConnection(HikariPool.java:162) ~[HikariCP-4.0.3.jar:?]
	at com.zaxxer.hikari.HikariDataSource.getConnection(HikariDataSource.java:128) ~[HikariCP-4.0.3.jar:?]
	at org.hibernate.engine.jdbc.connections.internal.DatasourceConnectionProviderImpl.getConnection(DatasourceConnectionProviderImpl.java:122) ~[hibernate-core-5.6.11.Final.jar:5.6.11.Final]
	at org.hibernate.internal.NonContextualJdbcConnectionAccess.obtainConnection(NonContextualJdbcConnectionAccess.java:38) ~[hibernate-core-5.6.11.Final.jar:5.6.11.Final]
	at org.hibernate.resource.jdbc.internal.LogicalConnectionManagedImpl.acquireConnectionIfNeeded(LogicalConnectionManagedImpl.java:108) ~[hibernate-core-5.6.11.Final.jar:5.6.11.Final]
	at org.hibernate.resource.jdbc.internal.LogicalConnectionManagedImpl.getPhysicalConnection(LogicalConnectionManagedImpl.java:138) ~[hibernate-core-5.6.11.Final.jar:5.6.11.Final]
	at org.hibernate.resource.jdbc.internal.LogicalConnectionManagedImpl.getConnectionForTransactionManagement(LogicalConnectionManagedImpl.java:276) ~[hibernate-core-5.6.11.Final.jar:5.6.11.Final]
	at org.hibernate.resource.jdbc.internal.LogicalConnectionManagedImpl.begin(LogicalConnectionManagedImpl.java:284) ~[hibernate-core-5.6.11.Final.jar:5.6.11.Final]
	at org.hibernate.resource.transaction.backend.jdbc.internal.JdbcResourceLocalTransactionCoordinatorImpl$TransactionDriverControlImpl.begin(JdbcResourceLocalTransactionCoordinatorImpl.java:246) ~[hibernate-core-5.6.11.Final.jar:5.6.11.Final]
	at org.hibernate.engine.transaction.internal.TransactionImpl.begin(TransactionImpl.java:83) ~[hibernate-core-5.6.11.Final.jar:5.6.11.Final]
	at org.springframework.orm.jpa.vendor.HibernateJpaDialect.beginTransaction(HibernateJpaDialect.java:164) ~[spring-orm-5.3.22.jar:5.3.22]
	at org.springframework.orm.jpa.JpaTransactionManager.doBegin(JpaTransactionManager.java:421) ~[spring-orm-5.3.22.jar:5.3.22]
	... 11 more
Caused by: com.mysql.cj.jdbc.exceptions.CommunicationsException: Communications link failure

The last packet sent successfully to the server was 0 milliseconds ago. The driver has not received any packets from the server.
	at com.mysql.cj.jdbc.exceptions.SQLError.createCommunicationsException(SQLError.java:174) ~[mysql-connector-java-8.0.30.jar:8.0.30]
	at com.mysql.cj.jdbc.exceptions.SQLExceptionsMapping.translateException(SQLExceptionsMapping.java:64) ~[mysql-connector-java-8.0.30.jar:8.0.30]
	at com.mysql.cj.jdbc.ConnectionImpl.createNewIO(ConnectionImpl.java:828) ~[mysql-connector-java-8.0.30.jar:8.0.30]
	at com.mysql.cj.jdbc.ConnectionImpl.<init>(ConnectionImpl.java:448) ~[mysql-connector-java-8.0.30.jar:8.0.30]
	at com.mysql.cj.jdbc.ConnectionImpl.getInstance(ConnectionImpl.java:241) ~[mysql-connector-java-8.0.30.jar:8.0.30]
	at com.mysql.cj.jdbc.NonRegisteringDriver.connect(NonRegisteringDriver.java:198) ~[mysql-connector-java-8.0.30.jar:8.0.30]
	at com.zaxxer.hikari.util.DriverDataSource.getConnection(DriverDataSource.java:138) ~[HikariCP-4.0.3.jar:?]
	at com.zaxxer.hikari.pool.PoolBase.newConnection(PoolBase.java:364) ~[HikariCP-4.0.3.jar:?]
	at com.zaxxer.hikari.pool.PoolBase.newPoolEntry(PoolBase.java:206) ~[HikariCP-4.0.3.jar:?]
	at com.zaxxer.hikari.pool.HikariPool.createPoolEntry(HikariPool.java:476) ~[HikariCP-4.0.3.jar:?]
	at com.zaxxer.hikari.pool.HikariPool.access$100(HikariPool.java:71) ~[HikariCP-4.0.3.jar:?]
	at com.zaxxer.hikari.pool.HikariPool$PoolEntryCreator.call(HikariPool.java:726) ~[HikariCP-4.0.3.jar:?]
	at com.zaxxer.hikari.pool.HikariPool$PoolEntryCreator.call(HikariPool.java:712) ~[HikariCP-4.0.3.jar:?]
	at java.util.concurrent.FutureTask.run(FutureTask.java:264) ~[?:?]
	at java.util.concurrent.ThreadPoolExecutor.runWorker(ThreadPoolExecutor.java:1128) ~[?:?]
	at java.util.concurrent.ThreadPoolExecutor$Worker.run(ThreadPoolExecutor.java:628) ~[?:?]
	... 1 more
Caused by: com.mysql.cj.exceptions.CJCommunicationsException: Communications link failure

The last packet sent successfully to the server was 0 milliseconds ago. The driver has not received any packets from the server.
	at jdk.internal.reflect.GeneratedConstructorAccessor491.newInstance(Unknown Source) ~[?:?]
	at jdk.internal.reflect.DelegatingConstructorAccessorImpl.newInstance(DelegatingConstructorAccessorImpl.java:45) ~[?:?]
	at java.lang.reflect.Constructor.newInstance(Constructor.java:490) ~[?:?]
	at com.mysql.cj.exceptions.ExceptionFactory.createException(ExceptionFactory.java:61) ~[mysql-connector-java-8.0.30.jar:8.0.30]
	at com.mysql.cj.exceptions.ExceptionFactory.createException(ExceptionFactory.java:105) ~[mysql-connector-java-8.0.30.jar:8.0.30]
	at com.mysql.cj.exceptions.ExceptionFactory.createException(ExceptionFactory.java:151) ~[mysql-connector-java-8.0.30.jar:8.0.30]
	at com.mysql.cj.exceptions.ExceptionFactory.createCommunicationsException(ExceptionFactory.java:167) ~[mysql-connector-java-8.0.30.jar:8.0.30]
	at com.mysql.cj.protocol.a.NativeSocketConnection.connect(NativeSocketConnection.java:89) ~[mysql-connector-java-8.0.30.jar:8.0.30]
	at com.mysql.cj.NativeSession.connect(NativeSession.java:120) ~[mysql-connector-java-8.0.30.jar:8.0.30]
	at com.mysql.cj.jdbc.ConnectionImpl.connectOneTryOnly(ConnectionImpl.java:948) ~[mysql-connector-java-8.0.30.jar:8.0.30]
	at com.mysql.cj.jdbc.ConnectionImpl.createNewIO(ConnectionImpl.java:818) ~[mysql-connector-java-8.0.30.jar:8.0.30]
	at com.mysql.cj.jdbc.ConnectionImpl.<init>(ConnectionImpl.java:448) ~[mysql-connector-java-8.0.30.jar:8.0.30]
	at com.mysql.cj.jdbc.ConnectionImpl.getInstance(ConnectionImpl.java:241) ~[mysql-connector-java-8.0.30.jar:8.0.30]
	at com.mysql.cj.jdbc.NonRegisteringDriver.connect(NonRegisteringDriver.java:198) ~[mysql-connector-java-8.0.30.jar:8.0.30]
	at com.zaxxer.hikari.util.DriverDataSource.getConnection(DriverDataSource.java:138) ~[HikariCP-4.0.3.jar:?]
	at com.zaxxer.hikari.pool.PoolBase.newConnection(PoolBase.java:364) ~[HikariCP-4.0.3.jar:?]
	at com.zaxxer.hikari.pool.PoolBase.newPoolEntry(PoolBase.java:206) ~[HikariCP-4.0.3.jar:?]
	at com.zaxxer.hikari.pool.HikariPool.createPoolEntry(HikariPool.java:476) ~[HikariCP-4.0.3.jar:?]
	at com.zaxxer.hikari.pool.HikariPool.access$100(HikariPool.java:71) ~[HikariCP-4.0.3.jar:?]
	at com.zaxxer.hikari.pool.HikariPool$PoolEntryCreator.call(HikariPool.java:726) ~[HikariCP-4.0.3.jar:?]
	at com.zaxxer.hikari.pool.HikariPool$PoolEntryCreator.call(HikariPool.java:712) ~[HikariCP-4.0.3.jar:?]
	at java.util.concurrent.FutureTask.run(FutureTask.java:264) ~[?:?]
	at java.util.concurrent.ThreadPoolExecutor.runWorker(ThreadPoolExecutor.java:1128) ~[?:?]
	at java.util.concurrent.ThreadPoolExecutor$Worker.run(ThreadPoolExecutor.java:628) ~[?:?]
	... 1 more
Caused by: java.net.UnknownHostException: No such host is known (freshersuperchargers.czbdrgtkozjs.us-east-1.rds.amazonaws.com)
	at java.net.Inet6AddressImpl.lookupAllHostAddr(Native Method) ~[?:?]
	at java.net.InetAddress$PlatformNameService.lookupAllHostAddr(InetAddress.java:929) ~[?:?]
	at java.net.InetAddress.getAddressesFromNameService(InetAddress.java:1538) ~[?:?]
	at java.net.InetAddress$NameServiceAddresses.get(InetAddress.java:848) ~[?:?]
	at java.net.InetAddress.getAllByName0(InetAddress.java:1527) ~[?:?]
	at java.net.InetAddress.getAllByName(InetAddress.java:1380) ~[?:?]
	at java.net.InetAddress.getAllByName(InetAddress.java:1302) ~[?:?]
	at com.mysql.cj.protocol.StandardSocketFactory.connect(StandardSocketFactory.java:130) ~[mysql-connector-java-8.0.30.jar:8.0.30]
	at com.mysql.cj.protocol.a.NativeSocketConnection.connect(NativeSocketConnection.java:63) ~[mysql-connector-java-8.0.30.jar:8.0.30]
	at com.mysql.cj.NativeSession.connect(NativeSession.java:120) ~[mysql-connector-java-8.0.30.jar:8.0.30]
	at com.mysql.cj.jdbc.ConnectionImpl.connectOneTryOnly(ConnectionImpl.java:948) ~[mysql-connector-java-8.0.30.jar:8.0.30]
	at com.mysql.cj.jdbc.ConnectionImpl.createNewIO(ConnectionImpl.java:818) ~[mysql-connector-java-8.0.30.jar:8.0.30]
	at com.mysql.cj.jdbc.ConnectionImpl.<init>(ConnectionImpl.java:448) ~[mysql-connector-java-8.0.30.jar:8.0.30]
	at com.mysql.cj.jdbc.ConnectionImpl.getInstance(ConnectionImpl.java:241) ~[mysql-connector-java-8.0.30.jar:8.0.30]
	at com.mysql.cj.jdbc.NonRegisteringDriver.connect(NonRegisteringDriver.java:198) ~[mysql-connector-java-8.0.30.jar:8.0.30]
	at com.zaxxer.hikari.util.DriverDataSource.getConnection(DriverDataSource.java:138) ~[HikariCP-4.0.3.jar:?]
	at com.zaxxer.hikari.pool.PoolBase.newConnection(PoolBase.java:364) ~[HikariCP-4.0.3.jar:?]
	at com.zaxxer.hikari.pool.PoolBase.newPoolEntry(PoolBase.java:206) ~[HikariCP-4.0.3.jar:?]
	at com.zaxxer.hikari.pool.HikariPool.createPoolEntry(HikariPool.java:476) ~[HikariCP-4.0.3.jar:?]
	at com.zaxxer.hikari.pool.HikariPool.access$100(HikariPool.java:71) ~[HikariCP-4.0.3.jar:?]
	at com.zaxxer.hikari.pool.HikariPool$PoolEntryCreator.call(HikariPool.java:726) ~[HikariCP-4.0.3.jar:?]
	at com.zaxxer.hikari.pool.HikariPool$PoolEntryCreator.call(HikariPool.java:712) ~[HikariCP-4.0.3.jar:?]
	at java.util.concurrent.FutureTask.run(FutureTask.java:264) ~[?:?]
	at java.util.concurrent.ThreadPoolExecutor.runWorker(ThreadPoolExecutor.java:1128) ~[?:?]
	at java.util.concurrent.ThreadPoolExecutor$Worker.run(ThreadPoolExecutor.java:628) ~[?:?]
	... 1 more
[2023-08-18 11:03:57,284] - [org.hibernate.engine.jdbc.spi.SqlExceptionHelper] [logExceptions] -> (WARN) [SQL Error: 0, SQLState: 08S01] 
[2023-08-18 11:03:57,285] - [org.hibernate.engine.jdbc.spi.SqlExceptionHelper] [logExceptions] -> (ERROR) [HikariPool-21 - Connection is not available, request timed out after 30001ms.] 
[2023-08-18 11:03:57,285] - [org.hibernate.engine.jdbc.spi.SqlExceptionHelper] [logExceptions] -> (ERROR) [Communications link failure

The last packet sent successfully to the server was 0 milliseconds ago. The driver has not received any packets from the server.] 
[2023-08-18 11:03:57,285] - [org.camunda.bpm.engine.jobexecutor] [logError] -> (ERROR) [ENGINE-14019 Exception during job acquisition Could not open JPA EntityManager for transaction; nested exception is org.hibernate.exception.JDBCConnectionException: Unable to acquire JDBC Connection] 
org.springframework.transaction.CannotCreateTransactionException: Could not open JPA EntityManager for transaction; nested exception is org.hibernate.exception.JDBCConnectionException: Unable to acquire JDBC Connection
	at org.springframework.orm.jpa.JpaTransactionManager.doBegin(JpaTransactionManager.java:467) ~[spring-orm-5.3.22.jar:5.3.22]
	at org.springframework.transaction.support.AbstractPlatformTransactionManager.startTransaction(AbstractPlatformTransactionManager.java:400) ~[spring-tx-5.3.22.jar:5.3.22]
	at org.springframework.transaction.support.AbstractPlatformTransactionManager.getTransaction(AbstractPlatformTransactionManager.java:373) ~[spring-tx-5.3.22.jar:5.3.22]
	at org.springframework.transaction.support.TransactionTemplate.execute(TransactionTemplate.java:137) ~[spring-tx-5.3.22.jar:5.3.22]
	at org.camunda.bpm.engine.spring.SpringTransactionInterceptor.execute(SpringTransactionInterceptor.java:71) ~[camunda-engine-spring-7.18.0.jar:7.18.0]
	at org.camunda.bpm.engine.impl.interceptor.ProcessApplicationContextInterceptor.execute(ProcessApplicationContextInterceptor.java:70) ~[camunda-engine-7.18.0.jar:7.18.0]
	at org.camunda.bpm.engine.impl.interceptor.CommandCounterInterceptor.execute(CommandCounterInterceptor.java:35) ~[camunda-engine-7.18.0.jar:7.18.0]
	at org.camunda.bpm.engine.impl.interceptor.LogInterceptor.execute(LogInterceptor.java:33) ~[camunda-engine-7.18.0.jar:7.18.0]
	at org.camunda.bpm.engine.impl.interceptor.ExceptionCodeInterceptor.execute(ExceptionCodeInterceptor.java:55) ~[camunda-engine-7.18.0.jar:7.18.0]
	at org.camunda.bpm.engine.impl.jobexecutor.SequentialJobAcquisitionRunnable.acquireJobs(SequentialJobAcquisitionRunnable.java:164) ~[camunda-engine-7.18.0.jar:7.18.0]
	at org.camunda.bpm.engine.impl.jobexecutor.SequentialJobAcquisitionRunnable.run(SequentialJobAcquisitionRunnable.java:80) ~[camunda-engine-7.18.0.jar:7.18.0]
	at java.lang.Thread.run(Thread.java:834) ~[?:?]
Caused by: org.hibernate.exception.JDBCConnectionException: Unable to acquire JDBC Connection
	at org.hibernate.exception.internal.SQLExceptionTypeDelegate.convert(SQLExceptionTypeDelegate.java:48) ~[hibernate-core-5.6.11.Final.jar:5.6.11.Final]
	at org.hibernate.exception.internal.StandardSQLExceptionConverter.convert(StandardSQLExceptionConverter.java:37) ~[hibernate-core-5.6.11.Final.jar:5.6.11.Final]
	at org.hibernate.engine.jdbc.spi.SqlExceptionHelper.convert(SqlExceptionHelper.java:113) ~[hibernate-core-5.6.11.Final.jar:5.6.11.Final]
	at org.hibernate.engine.jdbc.spi.SqlExceptionHelper.convert(SqlExceptionHelper.java:99) ~[hibernate-core-5.6.11.Final.jar:5.6.11.Final]
	at org.hibernate.resource.jdbc.internal.LogicalConnectionManagedImpl.acquireConnectionIfNeeded(LogicalConnectionManagedImpl.java:111) ~[hibernate-core-5.6.11.Final.jar:5.6.11.Final]
	at org.hibernate.resource.jdbc.internal.LogicalConnectionManagedImpl.getPhysicalConnection(LogicalConnectionManagedImpl.java:138) ~[hibernate-core-5.6.11.Final.jar:5.6.11.Final]
	at org.hibernate.resource.jdbc.internal.LogicalConnectionManagedImpl.getConnectionForTransactionManagement(LogicalConnectionManagedImpl.java:276) ~[hibernate-core-5.6.11.Final.jar:5.6.11.Final]
	at org.hibernate.resource.jdbc.internal.LogicalConnectionManagedImpl.begin(LogicalConnectionManagedImpl.java:284) ~[hibernate-core-5.6.11.Final.jar:5.6.11.Final]
	at org.hibernate.resource.transaction.backend.jdbc.internal.JdbcResourceLocalTransactionCoordinatorImpl$TransactionDriverControlImpl.begin(JdbcResourceLocalTransactionCoordinatorImpl.java:246) ~[hibernate-core-5.6.11.Final.jar:5.6.11.Final]
	at org.hibernate.engine.transaction.internal.TransactionImpl.begin(TransactionImpl.java:83) ~[hibernate-core-5.6.11.Final.jar:5.6.11.Final]
	at org.springframework.orm.jpa.vendor.HibernateJpaDialect.beginTransaction(HibernateJpaDialect.java:164) ~[spring-orm-5.3.22.jar:5.3.22]
	at org.springframework.orm.jpa.JpaTransactionManager.doBegin(JpaTransactionManager.java:421) ~[spring-orm-5.3.22.jar:5.3.22]
	... 11 more
Caused by: java.sql.SQLTransientConnectionException: HikariPool-21 - Connection is not available, request timed out after 30001ms.
	at com.zaxxer.hikari.pool.HikariPool.createTimeoutException(HikariPool.java:696) ~[HikariCP-4.0.3.jar:?]
	at com.zaxxer.hikari.pool.HikariPool.getConnection(HikariPool.java:197) ~[HikariCP-4.0.3.jar:?]
	at com.zaxxer.hikari.pool.HikariPool.getConnection(HikariPool.java:162) ~[HikariCP-4.0.3.jar:?]
	at com.zaxxer.hikari.HikariDataSource.getConnection(HikariDataSource.java:128) ~[HikariCP-4.0.3.jar:?]
	at org.hibernate.engine.jdbc.connections.internal.DatasourceConnectionProviderImpl.getConnection(DatasourceConnectionProviderImpl.java:122) ~[hibernate-core-5.6.11.Final.jar:5.6.11.Final]
	at org.hibernate.internal.NonContextualJdbcConnectionAccess.obtainConnection(NonContextualJdbcConnectionAccess.java:38) ~[hibernate-core-5.6.11.Final.jar:5.6.11.Final]
	at org.hibernate.resource.jdbc.internal.LogicalConnectionManagedImpl.acquireConnectionIfNeeded(LogicalConnectionManagedImpl.java:108) ~[hibernate-core-5.6.11.Final.jar:5.6.11.Final]
	at org.hibernate.resource.jdbc.internal.LogicalConnectionManagedImpl.getPhysicalConnection(LogicalConnectionManagedImpl.java:138) ~[hibernate-core-5.6.11.Final.jar:5.6.11.Final]
	at org.hibernate.resource.jdbc.internal.LogicalConnectionManagedImpl.getConnectionForTransactionManagement(LogicalConnectionManagedImpl.java:276) ~[hibernate-core-5.6.11.Final.jar:5.6.11.Final]
	at org.hibernate.resource.jdbc.internal.LogicalConnectionManagedImpl.begin(LogicalConnectionManagedImpl.java:284) ~[hibernate-core-5.6.11.Final.jar:5.6.11.Final]
	at org.hibernate.resource.transaction.backend.jdbc.internal.JdbcResourceLocalTransactionCoordinatorImpl$TransactionDriverControlImpl.begin(JdbcResourceLocalTransactionCoordinatorImpl.java:246) ~[hibernate-core-5.6.11.Final.jar:5.6.11.Final]
	at org.hibernate.engine.transaction.internal.TransactionImpl.begin(TransactionImpl.java:83) ~[hibernate-core-5.6.11.Final.jar:5.6.11.Final]
	at org.springframework.orm.jpa.vendor.HibernateJpaDialect.beginTransaction(HibernateJpaDialect.java:164) ~[spring-orm-5.3.22.jar:5.3.22]
	at org.springframework.orm.jpa.JpaTransactionManager.doBegin(JpaTransactionManager.java:421) ~[spring-orm-5.3.22.jar:5.3.22]
	... 11 more
Caused by: com.mysql.cj.jdbc.exceptions.CommunicationsException: Communications link failure

The last packet sent successfully to the server was 0 milliseconds ago. The driver has not received any packets from the server.
	at com.mysql.cj.jdbc.exceptions.SQLError.createCommunicationsException(SQLError.java:174) ~[mysql-connector-java-8.0.30.jar:8.0.30]
	at com.mysql.cj.jdbc.exceptions.SQLExceptionsMapping.translateException(SQLExceptionsMapping.java:64) ~[mysql-connector-java-8.0.30.jar:8.0.30]
	at com.mysql.cj.jdbc.ConnectionImpl.createNewIO(ConnectionImpl.java:828) ~[mysql-connector-java-8.0.30.jar:8.0.30]
	at com.mysql.cj.jdbc.ConnectionImpl.<init>(ConnectionImpl.java:448) ~[mysql-connector-java-8.0.30.jar:8.0.30]
	at com.mysql.cj.jdbc.ConnectionImpl.getInstance(ConnectionImpl.java:241) ~[mysql-connector-java-8.0.30.jar:8.0.30]
	at com.mysql.cj.jdbc.NonRegisteringDriver.connect(NonRegisteringDriver.java:198) ~[mysql-connector-java-8.0.30.jar:8.0.30]
	at com.zaxxer.hikari.util.DriverDataSource.getConnection(DriverDataSource.java:138) ~[HikariCP-4.0.3.jar:?]
	at com.zaxxer.hikari.pool.PoolBase.newConnection(PoolBase.java:364) ~[HikariCP-4.0.3.jar:?]
	at com.zaxxer.hikari.pool.PoolBase.newPoolEntry(PoolBase.java:206) ~[HikariCP-4.0.3.jar:?]
	at com.zaxxer.hikari.pool.HikariPool.createPoolEntry(HikariPool.java:476) ~[HikariCP-4.0.3.jar:?]
	at com.zaxxer.hikari.pool.HikariPool.access$100(HikariPool.java:71) ~[HikariCP-4.0.3.jar:?]
	at com.zaxxer.hikari.pool.HikariPool$PoolEntryCreator.call(HikariPool.java:726) ~[HikariCP-4.0.3.jar:?]
	at com.zaxxer.hikari.pool.HikariPool$PoolEntryCreator.call(HikariPool.java:712) ~[HikariCP-4.0.3.jar:?]
	at java.util.concurrent.FutureTask.run(FutureTask.java:264) ~[?:?]
	at java.util.concurrent.ThreadPoolExecutor.runWorker(ThreadPoolExecutor.java:1128) ~[?:?]
	at java.util.concurrent.ThreadPoolExecutor$Worker.run(ThreadPoolExecutor.java:628) ~[?:?]
	... 1 more
Caused by: com.mysql.cj.exceptions.CJCommunicationsException: Communications link failure

The last packet sent successfully to the server was 0 milliseconds ago. The driver has not received any packets from the server.
	at jdk.internal.reflect.GeneratedConstructorAccessor491.newInstance(Unknown Source) ~[?:?]
	at jdk.internal.reflect.DelegatingConstructorAccessorImpl.newInstance(DelegatingConstructorAccessorImpl.java:45) ~[?:?]
	at java.lang.reflect.Constructor.newInstance(Constructor.java:490) ~[?:?]
	at com.mysql.cj.exceptions.ExceptionFactory.createException(ExceptionFactory.java:61) ~[mysql-connector-java-8.0.30.jar:8.0.30]
	at com.mysql.cj.exceptions.ExceptionFactory.createException(ExceptionFactory.java:105) ~[mysql-connector-java-8.0.30.jar:8.0.30]
	at com.mysql.cj.exceptions.ExceptionFactory.createException(ExceptionFactory.java:151) ~[mysql-connector-java-8.0.30.jar:8.0.30]
	at com.mysql.cj.exceptions.ExceptionFactory.createCommunicationsException(ExceptionFactory.java:167) ~[mysql-connector-java-8.0.30.jar:8.0.30]
	at com.mysql.cj.protocol.a.NativeSocketConnection.connect(NativeSocketConnection.java:89) ~[mysql-connector-java-8.0.30.jar:8.0.30]
	at com.mysql.cj.NativeSession.connect(NativeSession.java:120) ~[mysql-connector-java-8.0.30.jar:8.0.30]
	at com.mysql.cj.jdbc.ConnectionImpl.connectOneTryOnly(ConnectionImpl.java:948) ~[mysql-connector-java-8.0.30.jar:8.0.30]
	at com.mysql.cj.jdbc.ConnectionImpl.createNewIO(ConnectionImpl.java:818) ~[mysql-connector-java-8.0.30.jar:8.0.30]
	at com.mysql.cj.jdbc.ConnectionImpl.<init>(ConnectionImpl.java:448) ~[mysql-connector-java-8.0.30.jar:8.0.30]
	at com.mysql.cj.jdbc.ConnectionImpl.getInstance(ConnectionImpl.java:241) ~[mysql-connector-java-8.0.30.jar:8.0.30]
	at com.mysql.cj.jdbc.NonRegisteringDriver.connect(NonRegisteringDriver.java:198) ~[mysql-connector-java-8.0.30.jar:8.0.30]
	at com.zaxxer.hikari.util.DriverDataSource.getConnection(DriverDataSource.java:138) ~[HikariCP-4.0.3.jar:?]
	at com.zaxxer.hikari.pool.PoolBase.newConnection(PoolBase.java:364) ~[HikariCP-4.0.3.jar:?]
	at com.zaxxer.hikari.pool.PoolBase.newPoolEntry(PoolBase.java:206) ~[HikariCP-4.0.3.jar:?]
	at com.zaxxer.hikari.pool.HikariPool.createPoolEntry(HikariPool.java:476) ~[HikariCP-4.0.3.jar:?]
	at com.zaxxer.hikari.pool.HikariPool.access$100(HikariPool.java:71) ~[HikariCP-4.0.3.jar:?]
	at com.zaxxer.hikari.pool.HikariPool$PoolEntryCreator.call(HikariPool.java:726) ~[HikariCP-4.0.3.jar:?]
	at com.zaxxer.hikari.pool.HikariPool$PoolEntryCreator.call(HikariPool.java:712) ~[HikariCP-4.0.3.jar:?]
	at java.util.concurrent.FutureTask.run(FutureTask.java:264) ~[?:?]
	at java.util.concurrent.ThreadPoolExecutor.runWorker(ThreadPoolExecutor.java:1128) ~[?:?]
	at java.util.concurrent.ThreadPoolExecutor$Worker.run(ThreadPoolExecutor.java:628) ~[?:?]
	... 1 more
Caused by: java.net.UnknownHostException: No such host is known (freshersuperchargers.czbdrgtkozjs.us-east-1.rds.amazonaws.com)
	at java.net.Inet6AddressImpl.lookupAllHostAddr(Native Method) ~[?:?]
	at java.net.InetAddress$PlatformNameService.lookupAllHostAddr(InetAddress.java:929) ~[?:?]
	at java.net.InetAddress.getAddressesFromNameService(InetAddress.java:1538) ~[?:?]
	at java.net.InetAddress$NameServiceAddresses.get(InetAddress.java:848) ~[?:?]
	at java.net.InetAddress.getAllByName0(InetAddress.java:1527) ~[?:?]
	at java.net.InetAddress.getAllByName(InetAddress.java:1380) ~[?:?]
	at java.net.InetAddress.getAllByName(InetAddress.java:1302) ~[?:?]
	at com.mysql.cj.protocol.StandardSocketFactory.connect(StandardSocketFactory.java:130) ~[mysql-connector-java-8.0.30.jar:8.0.30]
	at com.mysql.cj.protocol.a.NativeSocketConnection.connect(NativeSocketConnection.java:63) ~[mysql-connector-java-8.0.30.jar:8.0.30]
	at com.mysql.cj.NativeSession.connect(NativeSession.java:120) ~[mysql-connector-java-8.0.30.jar:8.0.30]
	at com.mysql.cj.jdbc.ConnectionImpl.connectOneTryOnly(ConnectionImpl.java:948) ~[mysql-connector-java-8.0.30.jar:8.0.30]
	at com.mysql.cj.jdbc.ConnectionImpl.createNewIO(ConnectionImpl.java:818) ~[mysql-connector-java-8.0.30.jar:8.0.30]
	at com.mysql.cj.jdbc.ConnectionImpl.<init>(ConnectionImpl.java:448) ~[mysql-connector-java-8.0.30.jar:8.0.30]
	at com.mysql.cj.jdbc.ConnectionImpl.getInstance(ConnectionImpl.java:241) ~[mysql-connector-java-8.0.30.jar:8.0.30]
	at com.mysql.cj.jdbc.NonRegisteringDriver.connect(NonRegisteringDriver.java:198) ~[mysql-connector-java-8.0.30.jar:8.0.30]
	at com.zaxxer.hikari.util.DriverDataSource.getConnection(DriverDataSource.java:138) ~[HikariCP-4.0.3.jar:?]
	at com.zaxxer.hikari.pool.PoolBase.newConnection(PoolBase.java:364) ~[HikariCP-4.0.3.jar:?]
	at com.zaxxer.hikari.pool.PoolBase.newPoolEntry(PoolBase.java:206) ~[HikariCP-4.0.3.jar:?]
	at com.zaxxer.hikari.pool.HikariPool.createPoolEntry(HikariPool.java:476) ~[HikariCP-4.0.3.jar:?]
	at com.zaxxer.hikari.pool.HikariPool.access$100(HikariPool.java:71) ~[HikariCP-4.0.3.jar:?]
	at com.zaxxer.hikari.pool.HikariPool$PoolEntryCreator.call(HikariPool.java:726) ~[HikariCP-4.0.3.jar:?]
	at com.zaxxer.hikari.pool.HikariPool$PoolEntryCreator.call(HikariPool.java:712) ~[HikariCP-4.0.3.jar:?]
	at java.util.concurrent.FutureTask.run(FutureTask.java:264) ~[?:?]
	at java.util.concurrent.ThreadPoolExecutor.runWorker(ThreadPoolExecutor.java:1128) ~[?:?]
	at java.util.concurrent.ThreadPoolExecutor$Worker.run(ThreadPoolExecutor.java:628) ~[?:?]
	... 1 more
[2023-08-18 14:58:29,659] - [com.zaxxer.hikari.pool.HikariPool] [run] -> (WARN) [HikariPool-21 - Thread starvation or clock leap detected (housekeeper delta=1h46m9s961ms597Âµs100ns).] 
[2023-08-18 16:02:40,777] - [com.zaxxer.hikari.pool.HikariPool] [run] -> (WARN) [HikariPool-21 - Thread starvation or clock leap detected (housekeeper delta=18m10s280ms890Âµs200ns).] 
[2023-08-18 16:08:31,463] - [org.springframework.boot.devtools.autoconfigure.LocalDevToolsAutoConfiguration$RestartingClassPathChangeChangedEventListener] [onApplicationEvent] -> (INFO) [Restarting due to 1 class path change (0 additions, 0 deletions, 1 modification)] 
[2023-08-18 16:08:36,063] - [org.camunda.bpm.container] [logInfo] -> (INFO) [ENGINE-08051 Process application trainingWorkflowApplication undeployed] 
[2023-08-18 16:08:37,896] - [org.apache.coyote.http11.Http11NioProtocol] [log] -> (INFO) [Pausing ProtocolHandler ["http-nio-9002"]] 
[2023-08-18 16:08:37,897] - [org.apache.catalina.core.StandardService] [log] -> (INFO) [Stopping service [Tomcat]] 
[2023-08-18 16:08:37,923] - [org.apache.coyote.http11.Http11NioProtocol] [log] -> (INFO) [Stopping ProtocolHandler ["http-nio-9002"]] 
[2023-08-18 16:08:37,930] - [org.apache.coyote.http11.Http11NioProtocol] [log] -> (INFO) [Destroying ProtocolHandler ["http-nio-9002"]] 
[2023-08-18 16:08:43,459] - [org.camunda.bpm.engine.telemetry] [logWarn] -> (WARN) [ENGINE-28002 Could not send telemetry data. Reason: ConnectorRequestException with message 'HTCL-02007 Unable to execute HTTP request'. Set this logger to DEBUG/FINE for the full stacktrace.] 
[2023-08-18 16:08:43,833] - [org.camunda.bpm.engine.telemetry] [logWarn] -> (WARN) [ENGINE-28002 Could not send telemetry data. Reason: ConnectorRequestException with message 'HTCL-02007 Unable to execute HTTP request'. Set this logger to DEBUG/FINE for the full stacktrace.] 
[2023-08-18 16:08:44,219] - [org.camunda.bpm.engine.telemetry] [logWarn] -> (WARN) [ENGINE-28002 Could not send telemetry data. Reason: ConnectorRequestException with message 'HTCL-02007 Unable to execute HTTP request'. Set this logger to DEBUG/FINE for the full stacktrace.] 
[2023-08-18 16:08:44,220] - [org.camunda.bpm.engine.jobexecutor] [logInfo] -> (INFO) [ENGINE-14015 Shutting down the JobExecutor[org.camunda.bpm.engine.spring.components.jobexecutor.SpringJobExecutor]] 
[2023-08-18 16:08:44,220] - [org.camunda.bpm.engine.jobexecutor] [logInfo] -> (INFO) [ENGINE-14020 JobExecutor[org.camunda.bpm.engine.spring.components.jobexecutor.SpringJobExecutor] stopped job acquisition] 
[2023-08-18 16:08:45,112] - [org.camunda.bpm.engine] [logInfo] -> (INFO) [ENGINE-00007 Process Engine default closed] 
[2023-08-18 16:08:45,115] - [org.springframework.orm.jpa.LocalContainerEntityManagerFactoryBean] [destroy] -> (INFO) [Closing JPA EntityManagerFactory for persistence unit 'default'] 
[2023-08-18 16:08:45,124] - [com.zaxxer.hikari.HikariDataSource] [close] -> (INFO) [HikariPool-21 - Shutdown initiated...] 
[2023-08-18 16:08:47,354] - [com.zaxxer.hikari.HikariDataSource] [close] -> (INFO) [HikariPool-21 - Shutdown completed.] 
[2023-08-18 16:08:47,835] - [com.hcl.elch.freshersuperchargers.trainingworkflow.TrainingWorkflowApplication] [logStarting] -> (INFO) [Starting TrainingWorkflowApplication using Java 11.0.19 on LP-5CG0471VCD with PID 26464 (C:\Users\tausif.ahmad\Downloads\Mergedsandipan\FresherSuperChargers\target\classes started by tausif.ahmad in C:\Users\tausif.ahmad\Downloads\Mergedsandipan\FresherSuperChargers)] 
[2023-08-18 16:08:47,837] - [com.hcl.elch.freshersuperchargers.trainingworkflow.TrainingWorkflowApplication] [logStartupProfileInfo] -> (INFO) [No active profile set, falling back to 1 default profile: "default"] 
[2023-08-18 16:08:48,481] - [org.springframework.data.repository.config.RepositoryConfigurationDelegate] [registerRepositoriesIn] -> (INFO) [Bootstrapping Spring Data JPA repositories in DEFAULT mode.] 
[2023-08-18 16:08:48,591] - [org.springframework.data.repository.config.RepositoryConfigurationDelegate] [registerRepositoriesIn] -> (INFO) [Finished Spring Data repository scanning in 109 ms. Found 9 JPA repository interfaces.] 
[2023-08-18 16:08:48,903] - [org.springframework.boot.web.embedded.tomcat.TomcatWebServer] [initialize] -> (INFO) [Tomcat initialized with port(s): 9002 (http)] 
[2023-08-18 16:08:48,904] - [org.apache.coyote.http11.Http11NioProtocol] [log] -> (INFO) [Initializing ProtocolHandler ["http-nio-9002"]] 
[2023-08-18 16:08:48,904] - [org.apache.catalina.core.StandardService] [log] -> (INFO) [Starting service [Tomcat]] 
[2023-08-18 16:08:48,905] - [org.apache.catalina.core.StandardEngine] [log] -> (INFO) [Starting Servlet engine: [Apache Tomcat/9.0.65]] 
[2023-08-18 16:08:49,052] - [org.apache.catalina.core.ContainerBase.[Tomcat-6].[localhost].[/]] [log] -> (INFO) [Initializing Spring embedded WebApplicationContext] 
[2023-08-18 16:08:49,052] - [org.springframework.boot.web.servlet.context.ServletWebServerApplicationContext] [prepareWebApplicationContext] -> (INFO) [Root WebApplicationContext: initialization completed in 1208 ms] 
[2023-08-18 16:08:49,064] - [org.camunda.bpm.spring.boot.starter.rest.CamundaJerseyResourceConfig] [registerCamundaRestResources] -> (INFO) [Configuring camunda rest api.] 
[2023-08-18 16:08:49,065] - [org.camunda.bpm.spring.boot.starter.rest.CamundaJerseyResourceConfig] [registerCamundaRestResources] -> (INFO) [Finished configuring camunda rest api.] 
[2023-08-18 16:08:49,260] - [org.hibernate.jpa.internal.util.LogHelper] [logPersistenceUnitInformation] -> (INFO) [HHH000204: Processing PersistenceUnitInfo [name: default]] 
[2023-08-18 16:08:49,275] - [com.zaxxer.hikari.HikariDataSource] [getConnection] -> (INFO) [HikariPool-22 - Starting...] 
[2023-08-18 16:08:54,028] - [com.zaxxer.hikari.HikariDataSource] [getConnection] -> (INFO) [HikariPool-22 - Start completed.] 
[2023-08-18 16:08:54,029] - [org.hibernate.dialect.Dialect] [<init>] -> (INFO) [HHH000400: Using dialect: org.hibernate.dialect.MySQL5InnoDBDialect] 
[2023-08-18 16:08:58,499] - [org.hibernate.engine.transaction.jta.platform.internal.JtaPlatformInitiator] [initiateService] -> (INFO) [HHH000490: Using JtaPlatform implementation: [org.hibernate.engine.transaction.jta.platform.internal.NoJtaPlatform]] 
[2023-08-18 16:08:58,500] - [org.springframework.orm.jpa.LocalContainerEntityManagerFactoryBean] [buildNativeEntityManagerFactory] -> (INFO) [Initialized JPA EntityManagerFactory for persistence unit 'default'] 
[2023-08-18 16:08:58,545] - [org.camunda.bpm.spring.boot] [logInfo] -> (INFO) [STARTER-SB040 Setting up jobExecutor with corePoolSize=3, maxPoolSize:10] 
[2023-08-18 16:08:58,626] - [org.camunda.bpm.engine.cfg] [logInfo] -> (INFO) [ENGINE-12003 Plugin 'CompositeProcessEnginePlugin[genericPropertiesConfiguration, camundaProcessEngineConfiguration, camundaDatasourceConfiguration, camundaJpaConfiguration, camundaJobConfiguration, camundaHistoryConfiguration, camundaMetricsConfiguration, camundaAuthorizationConfiguration, CreateAdminUserConfiguration[adminUser=AdminUserProperty[id=Test, firstName=Test, lastName=Test, email=Test@localhost, password=******]], failedJobConfiguration, disableDeploymentResourcePattern, eventPublisherPlugin, ApplicationContextClassloaderSwitchPlugin, SpringBootSpinProcessEnginePlugin]' activated on process engine 'default'] 
[2023-08-18 16:08:58,627] - [org.camunda.bpm.spring.boot] [logInfo] -> (INFO) [STARTER-SB020 ProcessApplication enabled: autoDeployment via springConfiguration#deploymentResourcePattern is disabled] 
[2023-08-18 16:08:58,627] - [org.camunda.bpm.spring.boot.starter.event.EventPublisherPlugin] [preInit] -> (INFO) [EVENTING-001: Initialized Camunda Spring Boot Eventing Engine Plugin.] 
[2023-08-18 16:08:58,627] - [org.camunda.bpm.spring.boot.starter.event.EventPublisherPlugin] [preInit] -> (INFO) [EVENTING-003: Task events will be published as Spring Events.] 
[2023-08-18 16:08:58,627] - [org.camunda.bpm.spring.boot.starter.event.EventPublisherPlugin] [preInit] -> (INFO) [EVENTING-005: Execution events will be published as Spring Events.] 
[2023-08-18 16:08:58,627] - [org.camunda.bpm.spring.boot.starter.event.EventPublisherPlugin] [preInit] -> (INFO) [EVENTING-007: History events will be published as Spring events.] 
[2023-08-18 16:08:58,629] - [org.camunda.spin] [logInfo] -> (INFO) [SPIN-01010 Discovered Spin data format provider: org.camunda.spin.impl.json.jackson.format.JacksonJsonDataFormatProvider[name = application/json]] 
[2023-08-18 16:08:58,632] - [org.camunda.spin] [logInfo] -> (INFO) [SPIN-01010 Discovered Spin data format provider: org.camunda.spin.impl.xml.dom.format.DomXmlDataFormatProvider[name = application/xml]] 
[2023-08-18 16:08:58,652] - [org.camunda.spin] [logInfo] -> (INFO) [SPIN-01009 Discovered Spin data format: org.camunda.spin.impl.xml.dom.format.DomXmlDataFormat[name = application/xml]] 
[2023-08-18 16:08:58,652] - [org.camunda.spin] [logInfo] -> (INFO) [SPIN-01009 Discovered Spin data format: org.camunda.spin.impl.json.jackson.format.JacksonJsonDataFormat[name = application/json]] 
[2023-08-18 16:08:58,657] - [org.camunda.bpm.dmn.feel.scala] [logInfo] -> (INFO) [FEEL/SCALA-01001 Spin value mapper detected] 
[2023-08-18 16:08:58,658] - [org.camunda.feel.FeelEngine] [<init>] -> (INFO) [Engine created. [value-mapper: CompositeValueMapper(List(org.camunda.feel.impl.JavaValueMapper@79ff77cb, org.camunda.spin.plugin.impl.feel.integration.SpinValueMapper@7ee208db)), function-provider: org.camunda.bpm.dmn.feel.impl.scala.function.CustomFunctionTransformer@694a36f8, clock: SystemClock, configuration: Configuration(false)]] 
[2023-08-18 16:09:11,199] - [org.camunda.bpm.engine] [logInfo] -> (INFO) [ENGINE-00001 Process Engine default created.] 
[2023-08-18 16:09:12,743] - [org.camunda.bpm.spring.boot] [logInfo] -> (INFO) [STARTER-SB011 Skip creating initial Admin User, user does exist: UserEntity[id=Test, revision=1, firstName=Test, lastName=Test, email=Test@localhost, password={SHA-512}Dj4moHOaoaqEM74EyY55rGbjaCa01vDaUF+rtUVBhiRRHOlyV8/RODY0eewl8r5qMUf4PbXQDKoJ0IX68ZjfFw==, salt=u0tNNyaUZBmqHQgKd2E2Xg==, lockExpirationTime=null, attempts=0]] 
[2023-08-18 16:09:12,772] - [org.drools.compiler.kie.builder.impl.KieBuilderImpl] [packageNameForFile] -> (WARN) [File 'rules/tasks.drl' is in folder 'rules' but declares package 'com.foobat'. It is advised to have a correspondance between package and folder names.] 
[2023-08-18 16:09:13,298] - [org.springframework.boot.autoconfigure.orm.jpa.JpaBaseConfiguration$JpaWebConfiguration] [openEntityManagerInViewInterceptor] -> (WARN) [spring.jpa.open-in-view is enabled by default. Therefore, database queries may be performed during view rendering. Explicitly configure spring.jpa.open-in-view to disable this warning] 
[2023-08-18 16:09:13,524] - [org.camunda.bpm.spring.boot.starter.webapp.filter.LazyInitRegistration] [lazyInit] -> (INFO) [lazy initialized org.camunda.bpm.spring.boot.starter.webapp.filter.LazySecurityFilter@a19d368] 
[2023-08-18 16:09:13,524] - [org.camunda.bpm.spring.boot.starter.webapp.filter.LazyInitRegistration] [lazyInit] -> (INFO) [lazy initialized org.camunda.bpm.spring.boot.starter.webapp.filter.LazyProcessEnginesFilter@39210563] 
[2023-08-18 16:09:13,605] - [org.springframework.boot.devtools.autoconfigure.OptionalLiveReloadServer] [startServer] -> (INFO) [LiveReload server is running on port 35729] 
[2023-08-18 16:09:13,645] - [org.apache.coyote.http11.Http11NioProtocol] [log] -> (INFO) [Starting ProtocolHandler ["http-nio-9002"]] 
[2023-08-18 16:09:13,674] - [org.springframework.boot.web.embedded.tomcat.TomcatWebServer] [start] -> (INFO) [Tomcat started on port(s): 9002 (http) with context path ''] 
[2023-08-18 16:09:13,685] - [org.camunda.bpm.container] [logInfo] -> (INFO) [ENGINE-08024 Found processes.xml file at file:/C:/Users/tausif.ahmad/Downloads/Mergedsandipan/FresherSuperChargers/target/classes/META-INF/processes.xml] 
[2023-08-18 16:09:13,757] - [org.camunda.bpm.container] [logInfo] -> (INFO) [ENGINE-08023 Deployment summary for process archive 'trainingWorkflowApplication': 

        userform.form
        training-workflow.bpmn
        userformPOC.form
] 
[2023-08-18 16:09:18,225] - [org.camunda.bpm.application] [logInfo] -> (INFO) [ENGINE-07021 ProcessApplication 'trainingWorkflowApplication' registered for DB deployments [5c39ab92-3d82-11ee-b945-1244bd7b236f, 79e7ab14-3db3-11ee-b000-085bd6a1e528, bd71b93c-3d87-11ee-bd83-86144da0bde2]. Will execute process definitions 

        Decision[version: 1, id: Decision:1:5c5ebfc6-3d82-11ee-b945-1244bd7b236f]
        Decision[version: 3, id: Decision:3:7a0e6cf8-3db3-11ee-b000-085bd6a1e528]
        Decision[version: 2, id: Decision:2:bdbf15f0-3d87-11ee-bd83-86144da0bde2]
Deployment does not provide any case definitions.] 
[2023-08-18 16:09:25,768] - [org.camunda.bpm.container] [logInfo] -> (INFO) [ENGINE-08050 Process application trainingWorkflowApplication successfully deployed] 
[2023-08-18 16:09:25,770] - [com.hcl.elch.freshersuperchargers.trainingworkflow.TrainingWorkflowApplication] [logStarted] -> (INFO) [Started TrainingWorkflowApplication in 38.07 seconds (JVM running for 89486.372)] 
[2023-08-18 16:09:25,772] - [org.springframework.boot.devtools.autoconfigure.ConditionEvaluationDeltaLoggingListener] [onApplicationEvent] -> (INFO) [Condition evaluation unchanged] 
[2023-08-18 16:09:25,773] - [org.camunda.bpm.engine.jobexecutor] [logInfo] -> (INFO) [ENGINE-14014 Starting up the JobExecutor[org.camunda.bpm.engine.spring.components.jobexecutor.SpringJobExecutor].] 
[2023-08-18 16:09:25,773] - [org.camunda.bpm.engine.jobexecutor] [logInfo] -> (INFO) [ENGINE-14018 JobExecutor[org.camunda.bpm.engine.spring.components.jobexecutor.SpringJobExecutor] starting to acquire jobs] 
[2023-08-18 16:14:12,424] - [org.camunda.bpm.engine.telemetry] [logWarn] -> (WARN) [ENGINE-28002 Could not send telemetry data. Reason: ConnectorRequestException with message 'HTCL-02007 Unable to execute HTTP request'. Set this logger to DEBUG/FINE for the full stacktrace.] 
[2023-08-18 16:14:12,795] - [org.camunda.bpm.engine.telemetry] [logWarn] -> (WARN) [ENGINE-28002 Could not send telemetry data. Reason: ConnectorRequestException with message 'HTCL-02007 Unable to execute HTTP request'. Set this logger to DEBUG/FINE for the full stacktrace.] 
[2023-08-18 16:14:13,174] - [org.camunda.bpm.engine.telemetry] [logWarn] -> (WARN) [ENGINE-28002 Could not send telemetry data. Reason: ConnectorRequestException with message 'HTCL-02007 Unable to execute HTTP request'. Set this logger to DEBUG/FINE for the full stacktrace.] 
[2023-08-18 19:07:20,808] - [org.springframework.boot.admin.SpringApplicationAdminMXBeanRegistrar$SpringApplicationAdmin] [shutdown] -> (INFO) [Application shutdown requested.] 
[2023-08-18 19:07:27,453] - [org.camunda.bpm.container] [logInfo] -> (INFO) [ENGINE-08051 Process application trainingWorkflowApplication undeployed] 
[2023-08-18 19:07:29,857] - [org.apache.coyote.http11.Http11NioProtocol] [log] -> (INFO) [Pausing ProtocolHandler ["http-nio-9002"]] 
[2023-08-18 19:07:29,858] - [org.apache.catalina.core.StandardService] [log] -> (INFO) [Stopping service [Tomcat]] 
[2023-08-18 19:07:29,886] - [org.apache.coyote.http11.Http11NioProtocol] [log] -> (INFO) [Stopping ProtocolHandler ["http-nio-9002"]] 
[2023-08-18 19:07:29,893] - [org.apache.coyote.http11.Http11NioProtocol] [log] -> (INFO) [Destroying ProtocolHandler ["http-nio-9002"]] 
[2023-08-18 19:07:35,584] - [org.camunda.bpm.engine.telemetry] [logWarn] -> (WARN) [ENGINE-28002 Could not send telemetry data. Reason: ConnectorRequestException with message 'HTCL-02007 Unable to execute HTTP request'. Set this logger to DEBUG/FINE for the full stacktrace.] 
[2023-08-18 19:07:35,996] - [org.camunda.bpm.engine.telemetry] [logWarn] -> (WARN) [ENGINE-28002 Could not send telemetry data. Reason: ConnectorRequestException with message 'HTCL-02007 Unable to execute HTTP request'. Set this logger to DEBUG/FINE for the full stacktrace.] 
[2023-08-18 19:07:36,390] - [org.camunda.bpm.engine.telemetry] [logWarn] -> (WARN) [ENGINE-28002 Could not send telemetry data. Reason: ConnectorRequestException with message 'HTCL-02007 Unable to execute HTTP request'. Set this logger to DEBUG/FINE for the full stacktrace.] 
[2023-08-18 19:07:36,390] - [org.camunda.bpm.engine.jobexecutor] [logInfo] -> (INFO) [ENGINE-14015 Shutting down the JobExecutor[org.camunda.bpm.engine.spring.components.jobexecutor.SpringJobExecutor]] 
[2023-08-18 19:07:36,391] - [org.camunda.bpm.engine.jobexecutor] [logInfo] -> (INFO) [ENGINE-14020 JobExecutor[org.camunda.bpm.engine.spring.components.jobexecutor.SpringJobExecutor] stopped job acquisition] 
[2023-08-18 19:07:37,312] - [org.camunda.bpm.engine] [logInfo] -> (INFO) [ENGINE-00007 Process Engine default closed] 
[2023-08-18 19:07:37,313] - [org.springframework.orm.jpa.LocalContainerEntityManagerFactoryBean] [destroy] -> (INFO) [Closing JPA EntityManagerFactory for persistence unit 'default'] 
[2023-08-18 19:07:37,318] - [com.zaxxer.hikari.HikariDataSource] [close] -> (INFO) [HikariPool-22 - Shutdown initiated...] 
[2023-08-18 19:07:39,629] - [com.zaxxer.hikari.HikariDataSource] [close] -> (INFO) [HikariPool-22 - Shutdown completed.] 
